Workbook

Sheet DIRECTIONS
A1: DIRECTIONS FOR SPREADSHEET USE
A2: MAKE SURE TO SAVE THIS SPREADSHEET AS A DIFFERENT NAME. | N2: Codes
N3: val | O3: valedictorian
A4: This spreadsheet can handle up to 416 students. | N4: sal | O4: salutorian
A5: Cell E22 must be filled out with the number of students walking on Class Day | N5: scp | O5: student council president
N6: cp | O6: class president
N7: c1 | O7: class officer 1 - usual vp
A8: Eliminate all rows after the last name. | N8: c2 | O8: class officer 2 - usual treasurer
N9: c3 | O9: class officer 3 - usually secretary
N10: c4 | O10: class officer
N11: c5 | O11: class officer
N12: c6 | O12: class officer
A13: Notes: | G13: New for 2015 | N13: c7 | O13: class officer
A14: NO ROOM FOR BAND | G14: Copy the names into the Raw Name Splitter Worksheet | N14: c8 | O14: class officer
A15: MARHALS SIT ROW B | G15: Fill out cell E22 DO NOT Count class officers | N15: c9 | O15: class officer
A16: Officers sit in row A | G16: Follow the steps on the next pages | N16: c10 | O16: class officer
A17: Band sits behind the seniors in remainder of Lower Sections | G17: The spreadsheet is now ready for merging with the instruction sheet. | N17: c11 | O17: class officer
A18: This is designed for the band to sit on the stage. | N18: x | O18: student is not walking
A22: Number of students walking on Class Day: | E22: 263
E23: =ROUND(E22/2,0)-1 -> 131
E24: =E22-E23 -> 132

Sheet Raw Name Splitter
A1: Raw Names From Office | C1: First Name | D1: Middle Name | E1: Last Name | F1: Pronouncation
A2: Jillian Kate Abate | C2: =IF(ISERROR( FIND(",",TRIM(A2))),LEFT(TRIM(A2), FIND(" ",TRIM(A2))-1),MID(TRIM(A2),LEN(C2)+3,FIND(" ",TRIM(A2)&" ",LEN(C2)+3)-LEN(C2)-2)) -> Jillian | D2: =IF(ISERROR(FIND(",",TRIM(A2))),IF(LEN(TRIM(A2))-LEN(SUBSTITUTE(TRIM(A2)," ",""))=2,MID(TRIM(A2),LEN(C2)+2,FIND(" ",TRIM(A2),LEN(C2)+2)-LEN(C2)-2),""),MID(TRIM(A2),3+LEN(C2)+LEN(E2),30)) -> Kate | E2: =IF(ISERROR(FIND(",",TRIM(A2))),MID(TRIM(A2),1+LEN(TRIM(A2))-LEN(SUBSTITUTE(TRIM(A2)," ",""))+LEN(C2)+LEN(D2),30),LEFT(TRIM(A2), FIND(",",TRIM(A2))-1)) -> Abate | F2: a-bod-ee | H2: STEP 1: | I2: Paste Name List Into Column A
A3: Logan Ford Abrams | C3: =IF(ISERROR( FIND(",",TRIM(A3))),LEFT(TRIM(A3), FIND(" ",TRIM(A3))-1),MID(TRIM(A3),LEN(C3)+3,FIND(" ",TRIM(A3)&" ",LEN(C3)+3)-LEN(C3)-2)) -> Logan | D3: =IF(ISERROR(FIND(",",TRIM(A3))),IF(LEN(TRIM(A3))-LEN(SUBSTITUTE(TRIM(A3)," ",""))=2,MID(TRIM(A3),LEN(C3)+2,FIND(" ",TRIM(A3),LEN(C3)+2)-LEN(C3)-2),""),MID(TRIM(A3),3+LEN(C3)+LEN(E3),30)) -> Ford | E3: =IF(ISERROR(FIND(",",TRIM(A3))),MID(TRIM(A3),1+LEN(TRIM(A3))-LEN(SUBSTITUTE(TRIM(A3)," ",""))+LEN(C3)+LEN(D3),30),LEFT(TRIM(A3), FIND(",",TRIM(A3))-1)) -> Abrams | H3: STEP 2: | I3: If there are spaces between the names in Column A, then Highlight all of the names and spaces, and click HOME, FIND&SELECT, GOTO, SPECIAL, BLANKS, and then Click DELETE or use CTRL+G, SPECIAL, BLANKS, then right click DELETE
A4: Raniya Abubakar | C4: =IF(ISERROR( FIND(",",TRIM(A4))),LEFT(TRIM(A4), FIND(" ",TRIM(A4))-1),MID(TRIM(A4),LEN(C4)+3,FIND(" ",TRIM(A4)&" ",LEN(C4)+3)-LEN(C4)-2)) -> Raniya | D4: =IF(ISERROR(FIND(",",TRIM(A4))),IF(LEN(TRIM(A4))-LEN(SUBSTITUTE(TRIM(A4)," ",""))=2,MID(TRIM(A4),LEN(C4)+2,FIND(" ",TRIM(A4),LEN(C4)+2)-LEN(C4)-2),""),MID(TRIM(A4),3+LEN(C4)+LEN(E4),30)) | E4: =IF(ISERROR(FIND(",",TRIM(A4))),MID(TRIM(A4),1+LEN(TRIM(A4))-LEN(SUBSTITUTE(TRIM(A4)," ",""))+LEN(C4)+LEN(D4),30),LEFT(TRIM(A4), FIND(",",TRIM(A4))-1)) -> Abubakar | F4: Raw-knee-yuh Uh-boo-buh-ker
A5: Luis Aburto Campos | C5: =IF(ISERROR( FIND(",",TRIM(A5))),LEFT(TRIM(A5), FIND(" ",TRIM(A5))-1),MID(TRIM(A5),LEN(C5)+3,FIND(" ",TRIM(A5)&" ",LEN(C5)+3)-LEN(C5)-2)) -> Luis | E5: Aburto Campos | F5: Lou eese Aburto Campos | H5: STEP 3: | I5: Fix Miss Spaced Names
A6: Devyn Ahlert | C6: =IF(ISERROR( FIND(",",TRIM(A6))),LEFT(TRIM(A6), FIND(" ",TRIM(A6))-1),MID(TRIM(A6),LEN(C6)+3,FIND(" ",TRIM(A6)&" ",LEN(C6)+3)-LEN(C6)-2)) -> Devyn | D6: =IF(ISERROR(FIND(",",TRIM(A6))),IF(LEN(TRIM(A6))-LEN(SUBSTITUTE(TRIM(A6)," ",""))=2,MID(TRIM(A6),LEN(C6)+2,FIND(" ",TRIM(A6),LEN(C6)+2)-LEN(C6)-2),""),MID(TRIM(A6),3+LEN(C6)+LEN(E6),30)) | E6: =IF(ISERROR(FIND(",",TRIM(A6))),MID(TRIM(A6),1+LEN(TRIM(A6))-LEN(SUBSTITUTE(TRIM(A6)," ",""))+LEN(C6)+LEN(D6),30),LEFT(TRIM(A6), FIND(",",TRIM(A6))-1)) -> Ahlert | F6: Dev-in AL-ert
A7: Alexander Aiello | C7: =IF(ISERROR( FIND(",",TRIM(A7))),LEFT(TRIM(A7), FIND(" ",TRIM(A7))-1),MID(TRIM(A7),LEN(C7)+3,FIND(" ",TRIM(A7)&" ",LEN(C7)+3)-LEN(C7)-2)) -> Alexander | D7: =IF(ISERROR(FIND(",",TRIM(A7))),IF(LEN(TRIM(A7))-LEN(SUBSTITUTE(TRIM(A7)," ",""))=2,MID(TRIM(A7),LEN(C7)+2,FIND(" ",TRIM(A7),LEN(C7)+2)-LEN(C7)-2),""),MID(TRIM(A7),3+LEN(C7)+LEN(E7),30)) | E7: =IF(ISERROR(FIND(",",TRIM(A7))),MID(TRIM(A7),1+LEN(TRIM(A7))-LEN(SUBSTITUTE(TRIM(A7)," ",""))+LEN(C7)+LEN(D7),30),LEFT(TRIM(A7), FIND(",",TRIM(A7))-1)) -> Aiello | F7: Aiello (I-L-O)
A8: Reese Allen | C8: =IF(ISERROR( FIND(",",TRIM(A8))),LEFT(TRIM(A8), FIND(" ",TRIM(A8))-1),MID(TRIM(A8),LEN(C8)+3,FIND(" ",TRIM(A8)&" ",LEN(C8)+3)-LEN(C8)-2)) -> Reese | D8: =IF(ISERROR(FIND(",",TRIM(A8))),IF(LEN(TRIM(A8))-LEN(SUBSTITUTE(TRIM(A8)," ",""))=2,MID(TRIM(A8),LEN(C8)+2,FIND(" ",TRIM(A8),LEN(C8)+2)-LEN(C8)-2),""),MID(TRIM(A8),3+LEN(C8)+LEN(E8),30)) | E8: =IF(ISERROR(FIND(",",TRIM(A8))),MID(TRIM(A8),1+LEN(TRIM(A8))-LEN(SUBSTITUTE(TRIM(A8)," ",""))+LEN(C8)+LEN(D8),30),LEFT(TRIM(A8), FIND(",",TRIM(A8))-1)) -> Allen | F8: Reese Allen
A9: Fabricio Amado | C9: =IF(ISERROR( FIND(",",TRIM(A9))),LEFT(TRIM(A9), FIND(" ",TRIM(A9))-1),MID(TRIM(A9),LEN(C9)+3,FIND(" ",TRIM(A9)&" ",LEN(C9)+3)-LEN(C9)-2)) -> Fabricio | D9: =IF(ISERROR(FIND(",",TRIM(A9))),IF(LEN(TRIM(A9))-LEN(SUBSTITUTE(TRIM(A9)," ",""))=2,MID(TRIM(A9),LEN(C9)+2,FIND(" ",TRIM(A9),LEN(C9)+2)-LEN(C9)-2),""),MID(TRIM(A9),3+LEN(C9)+LEN(E9),30)) | E9: =IF(ISERROR(FIND(",",TRIM(A9))),MID(TRIM(A9),1+LEN(TRIM(A9))-LEN(SUBSTITUTE(TRIM(A9)," ",""))+LEN(C9)+LEN(D9),30),LEFT(TRIM(A9), FIND(",",TRIM(A9))-1)) -> Amado | F9: Fah-bree-cee-oh Ah-mod-oh
A10: Joseph Amirault | C10: =IF(ISERROR( FIND(",",TRIM(A10))),LEFT(TRIM(A10), FIND(" ",TRIM(A10))-1),MID(TRIM(A10),LEN(C10)+3,FIND(" ",TRIM(A10)&" ",LEN(C10)+3)-LEN(C10)-2)) -> Joseph | D10: =IF(ISERROR(FIND(",",TRIM(A10))),IF(LEN(TRIM(A10))-LEN(SUBSTITUTE(TRIM(A10)," ",""))=2,MID(TRIM(A10),LEN(C10)+2,FIND(" ",TRIM(A10),LEN(C10)+2)-LEN(C10)-2),""),MID(TRIM(A10),3+LEN(C10)+LEN(E10),30)) | E10: =IF(ISERROR(FIND(",",TRIM(A10))),MID(TRIM(A10),1+LEN(TRIM(A10))-LEN(SUBSTITUTE(TRIM(A10)," ",""))+LEN(C10)+LEN(D10),30),LEFT(TRIM(A10), FIND(",",TRIM(A10))-1)) -> Amirault
A11: Brady Anderson | C11: =IF(ISERROR( FIND(",",TRIM(A11))),LEFT(TRIM(A11), FIND(" ",TRIM(A11))-1),MID(TRIM(A11),LEN(C11)+3,FIND(" ",TRIM(A11)&" ",LEN(C11)+3)-LEN(C11)-2)) -> Brady | D11: =IF(ISERROR(FIND(",",TRIM(A11))),IF(LEN(TRIM(A11))-LEN(SUBSTITUTE(TRIM(A11)," ",""))=2,MID(TRIM(A11),LEN(C11)+2,FIND(" ",TRIM(A11),LEN(C11)+2)-LEN(C11)-2),""),MID(TRIM(A11),3+LEN(C11)+LEN(E11),30)) | E11: =IF(ISERROR(FIND(",",TRIM(A11))),MID(TRIM(A11),1+LEN(TRIM(A11))-LEN(SUBSTITUTE(TRIM(A11)," ",""))+LEN(C11)+LEN(D11),30),LEFT(TRIM(A11), FIND(",",TRIM(A11))-1)) -> Anderson
A12: Barrington Anderson | C12: =IF(ISERROR( FIND(",",TRIM(A12))),LEFT(TRIM(A12), FIND(" ",TRIM(A12))-1),MID(TRIM(A12),LEN(C12)+3,FIND(" ",TRIM(A12)&" ",LEN(C12)+3)-LEN(C12)-2)) -> Barrington | D12: =IF(ISERROR(FIND(",",TRIM(A12))),IF(LEN(TRIM(A12))-LEN(SUBSTITUTE(TRIM(A12)," ",""))=2,MID(TRIM(A12),LEN(C12)+2,FIND(" ",TRIM(A12),LEN(C12)+2)-LEN(C12)-2),""),MID(TRIM(A12),3+LEN(C12)+LEN(E12),30)) | E12: =IF(ISERROR(FIND(",",TRIM(A12))),MID(TRIM(A12),1+LEN(TRIM(A12))-LEN(SUBSTITUTE(TRIM(A12)," ",""))+LEN(C12)+LEN(D12),30),LEFT(TRIM(A12), FIND(",",TRIM(A12))-1)) -> Anderson
A13: Isabella Aquino | C13: =IF(ISERROR( FIND(",",TRIM(A13))),LEFT(TRIM(A13), FIND(" ",TRIM(A13))-1),MID(TRIM(A13),LEN(C13)+3,FIND(" ",TRIM(A13)&" ",LEN(C13)+3)-LEN(C13)-2)) -> Isabella | D13: =IF(ISERROR(FIND(",",TRIM(A13))),IF(LEN(TRIM(A13))-LEN(SUBSTITUTE(TRIM(A13)," ",""))=2,MID(TRIM(A13),LEN(C13)+2,FIND(" ",TRIM(A13),LEN(C13)+2)-LEN(C13)-2),""),MID(TRIM(A13),3+LEN(C13)+LEN(E13),30)) | E13: =IF(ISERROR(FIND(",",TRIM(A13))),MID(TRIM(A13),1+LEN(TRIM(A13))-LEN(SUBSTITUTE(TRIM(A13)," ",""))+LEN(C13)+LEN(D13),30),LEFT(TRIM(A13), FIND(",",TRIM(A13))-1)) -> Aquino | F13: Isabell-uh Ah-kee-no
A14: Lucas Aquino | C14: =IF(ISERROR( FIND(",",TRIM(A14))),LEFT(TRIM(A14), FIND(" ",TRIM(A14))-1),MID(TRIM(A14),LEN(C14)+3,FIND(" ",TRIM(A14)&" ",LEN(C14)+3)-LEN(C14)-2)) -> Lucas | D14: =IF(ISERROR(FIND(",",TRIM(A14))),IF(LEN(TRIM(A14))-LEN(SUBSTITUTE(TRIM(A14)," ",""))=2,MID(TRIM(A14),LEN(C14)+2,FIND(" ",TRIM(A14),LEN(C14)+2)-LEN(C14)-2),""),MID(TRIM(A14),3+LEN(C14)+LEN(E14),30)) | E14: =IF(ISERROR(FIND(",",TRIM(A14))),MID(TRIM(A14),1+LEN(TRIM(A14))-LEN(SUBSTITUTE(TRIM(A14)," ",""))+LEN(C14)+LEN(D14),30),LEFT(TRIM(A14), FIND(",",TRIM(A14))-1)) -> Aquino
A15: Tiago Araujo | C15: =IF(ISERROR( FIND(",",TRIM(A15))),LEFT(TRIM(A15), FIND(" ",TRIM(A15))-1),MID(TRIM(A15),LEN(C15)+3,FIND(" ",TRIM(A15)&" ",LEN(C15)+3)-LEN(C15)-2)) -> Tiago | D15: =IF(ISERROR(FIND(",",TRIM(A15))),IF(LEN(TRIM(A15))-LEN(SUBSTITUTE(TRIM(A15)," ",""))=2,MID(TRIM(A15),LEN(C15)+2,FIND(" ",TRIM(A15),LEN(C15)+2)-LEN(C15)-2),""),MID(TRIM(A15),3+LEN(C15)+LEN(E15),30)) | E15: =IF(ISERROR(FIND(",",TRIM(A15))),MID(TRIM(A15),1+LEN(TRIM(A15))-LEN(SUBSTITUTE(TRIM(A15)," ",""))+LEN(C15)+LEN(D15),30),LEFT(TRIM(A15), FIND(",",TRIM(A15))-1)) -> Araujo | F15: TEE-ah-go AH-ra-joe
A16: Chloe Aretusi | C16: =IF(ISERROR( FIND(",",TRIM(A16))),LEFT(TRIM(A16), FIND(" ",TRIM(A16))-1),MID(TRIM(A16),LEN(C16)+3,FIND(" ",TRIM(A16)&" ",LEN(C16)+3)-LEN(C16)-2)) -> Chloe | D16: =IF(ISERROR(FIND(",",TRIM(A16))),IF(LEN(TRIM(A16))-LEN(SUBSTITUTE(TRIM(A16)," ",""))=2,MID(TRIM(A16),LEN(C16)+2,FIND(" ",TRIM(A16),LEN(C16)+2)-LEN(C16)-2),""),MID(TRIM(A16),3+LEN(C16)+LEN(E16),30)) | E16: =IF(ISERROR(FIND(",",TRIM(A16))),MID(TRIM(A16),1+LEN(TRIM(A16))-LEN(SUBSTITUTE(TRIM(A16)," ",""))+LEN(C16)+LEN(D16),30),LEFT(TRIM(A16), FIND(",",TRIM(A16))-1)) -> Aretusi | F16: ah-reh-toozy
A17: Evan Audley | C17: =IF(ISERROR( FIND(",",TRIM(A17))),LEFT(TRIM(A17), FIND(" ",TRIM(A17))-1),MID(TRIM(A17),LEN(C17)+3,FIND(" ",TRIM(A17)&" ",LEN(C17)+3)-LEN(C17)-2)) -> Evan | D17: =IF(ISERROR(FIND(",",TRIM(A17))),IF(LEN(TRIM(A17))-LEN(SUBSTITUTE(TRIM(A17)," ",""))=2,MID(TRIM(A17),LEN(C17)+2,FIND(" ",TRIM(A17),LEN(C17)+2)-LEN(C17)-2),""),MID(TRIM(A17),3+LEN(C17)+LEN(E17),30)) | E17: =IF(ISERROR(FIND(",",TRIM(A17))),MID(TRIM(A17),1+LEN(TRIM(A17))-LEN(SUBSTITUTE(TRIM(A17)," ",""))+LEN(C17)+LEN(D17),30),LEFT(TRIM(A17), FIND(",",TRIM(A17))-1)) -> Audley
A18: Natalie Austin | C18: =IF(ISERROR( FIND(",",TRIM(A18))),LEFT(TRIM(A18), FIND(" ",TRIM(A18))-1),MID(TRIM(A18),LEN(C18)+3,FIND(" ",TRIM(A18)&" ",LEN(C18)+3)-LEN(C18)-2)) -> Natalie | D18: =IF(ISERROR(FIND(",",TRIM(A18))),IF(LEN(TRIM(A18))-LEN(SUBSTITUTE(TRIM(A18)," ",""))=2,MID(TRIM(A18),LEN(C18)+2,FIND(" ",TRIM(A18),LEN(C18)+2)-LEN(C18)-2),""),MID(TRIM(A18),3+LEN(C18)+LEN(E18),30)) | E18: =IF(ISERROR(FIND(",",TRIM(A18))),MID(TRIM(A18),1+LEN(TRIM(A18))-LEN(SUBSTITUTE(TRIM(A18)," ",""))+LEN(C18)+LEN(D18),30),LEFT(TRIM(A18), FIND(",",TRIM(A18))-1)) -> Austin
A19: Vivian Balas | C19: =IF(ISERROR( FIND(",",TRIM(A19))),LEFT(TRIM(A19), FIND(" ",TRIM(A19))-1),MID(TRIM(A19),LEN(C19)+3,FIND(" ",TRIM(A19)&" ",LEN(C19)+3)-LEN(C19)-2)) -> Vivian | D19: =IF(ISERROR(FIND(",",TRIM(A19))),IF(LEN(TRIM(A19))-LEN(SUBSTITUTE(TRIM(A19)," ",""))=2,MID(TRIM(A19),LEN(C19)+2,FIND(" ",TRIM(A19),LEN(C19)+2)-LEN(C19)-2),""),MID(TRIM(A19),3+LEN(C19)+LEN(E19),30)) | E19: =IF(ISERROR(FIND(",",TRIM(A19))),MID(TRIM(A19),1+LEN(TRIM(A19))-LEN(SUBSTITUTE(TRIM(A19)," ",""))+LEN(C19)+LEN(D19),30),LEFT(TRIM(A19), FIND(",",TRIM(A19))-1)) -> Balas
A20: Kaua Batista | C20: =IF(ISERROR( FIND(",",TRIM(A20))),LEFT(TRIM(A20), FIND(" ",TRIM(A20))-1),MID(TRIM(A20),LEN(C20)+3,FIND(" ",TRIM(A20)&" ",LEN(C20)+3)-LEN(C20)-2)) -> Kaua | D20: =IF(ISERROR(FIND(",",TRIM(A20))),IF(LEN(TRIM(A20))-LEN(SUBSTITUTE(TRIM(A20)," ",""))=2,MID(TRIM(A20),LEN(C20)+2,FIND(" ",TRIM(A20),LEN(C20)+2)-LEN(C20)-2),""),MID(TRIM(A20),3+LEN(C20)+LEN(E20),30)) | E20: =IF(ISERROR(FIND(",",TRIM(A20))),MID(TRIM(A20),1+LEN(TRIM(A20))-LEN(SUBSTITUTE(TRIM(A20)," ",""))+LEN(C20)+LEN(D20),30),LEFT(TRIM(A20), FIND(",",TRIM(A20))-1)) -> Batista | F20: Quan
A21: Carson Beaulieu | C21: =IF(ISERROR( FIND(",",TRIM(A21))),LEFT(TRIM(A21), FIND(" ",TRIM(A21))-1),MID(TRIM(A21),LEN(C21)+3,FIND(" ",TRIM(A21)&" ",LEN(C21)+3)-LEN(C21)-2)) -> Carson | D21: =IF(ISERROR(FIND(",",TRIM(A21))),IF(LEN(TRIM(A21))-LEN(SUBSTITUTE(TRIM(A21)," ",""))=2,MID(TRIM(A21),LEN(C21)+2,FIND(" ",TRIM(A21),LEN(C21)+2)-LEN(C21)-2),""),MID(TRIM(A21),3+LEN(C21)+LEN(E21),30)) | E21: =IF(ISERROR(FIND(",",TRIM(A21))),MID(TRIM(A21),1+LEN(TRIM(A21))-LEN(SUBSTITUTE(TRIM(A21)," ",""))+LEN(C21)+LEN(D21),30),LEFT(TRIM(A21), FIND(",",TRIM(A21))-1)) -> Beaulieu | F21: Bowl-ee-oh
A22: Jahnai Belfon | C22: =IF(ISERROR( FIND(",",TRIM(A22))),LEFT(TRIM(A22), FIND(" ",TRIM(A22))-1),MID(TRIM(A22),LEN(C22)+3,FIND(" ",TRIM(A22)&" ",LEN(C22)+3)-LEN(C22)-2)) -> Jahnai | D22: =IF(ISERROR(FIND(",",TRIM(A22))),IF(LEN(TRIM(A22))-LEN(SUBSTITUTE(TRIM(A22)," ",""))=2,MID(TRIM(A22),LEN(C22)+2,FIND(" ",TRIM(A22),LEN(C22)+2)-LEN(C22)-2),""),MID(TRIM(A22),3+LEN(C22)+LEN(E22),30)) | E22: =IF(ISERROR(FIND(",",TRIM(A22))),MID(TRIM(A22),1+LEN(TRIM(A22))-LEN(SUBSTITUTE(TRIM(A22)," ",""))+LEN(C22)+LEN(D22),30),LEFT(TRIM(A22), FIND(",",TRIM(A22))-1)) -> Belfon | F22: Jah-nye
A23: Amelia Benedict | C23: =IF(ISERROR( FIND(",",TRIM(A23))),LEFT(TRIM(A23), FIND(" ",TRIM(A23))-1),MID(TRIM(A23),LEN(C23)+3,FIND(" ",TRIM(A23)&" ",LEN(C23)+3)-LEN(C23)-2)) -> Amelia | D23: =IF(ISERROR(FIND(",",TRIM(A23))),IF(LEN(TRIM(A23))-LEN(SUBSTITUTE(TRIM(A23)," ",""))=2,MID(TRIM(A23),LEN(C23)+2,FIND(" ",TRIM(A23),LEN(C23)+2)-LEN(C23)-2),""),MID(TRIM(A23),3+LEN(C23)+LEN(E23),30)) | E23: =IF(ISERROR(FIND(",",TRIM(A23))),MID(TRIM(A23),1+LEN(TRIM(A23))-LEN(SUBSTITUTE(TRIM(A23)," ",""))+LEN(C23)+LEN(D23),30),LEFT(TRIM(A23), FIND(",",TRIM(A23))-1)) -> Benedict
A24: Jamison Bentley | C24: =IF(ISERROR( FIND(",",TRIM(A24))),LEFT(TRIM(A24), FIND(" ",TRIM(A24))-1),MID(TRIM(A24),LEN(C24)+3,FIND(" ",TRIM(A24)&" ",LEN(C24)+3)-LEN(C24)-2)) -> Jamison | D24: =IF(ISERROR(FIND(",",TRIM(A24))),IF(LEN(TRIM(A24))-LEN(SUBSTITUTE(TRIM(A24)," ",""))=2,MID(TRIM(A24),LEN(C24)+2,FIND(" ",TRIM(A24),LEN(C24)+2)-LEN(C24)-2),""),MID(TRIM(A24),3+LEN(C24)+LEN(E24),30)) | E24: =IF(ISERROR(FIND(",",TRIM(A24))),MID(TRIM(A24),1+LEN(TRIM(A24))-LEN(SUBSTITUTE(TRIM(A24)," ",""))+LEN(C24)+LEN(D24),30),LEFT(TRIM(A24), FIND(",",TRIM(A24))-1)) -> Bentley
A25: Dhanya Bhola | C25: =IF(ISERROR( FIND(",",TRIM(A25))),LEFT(TRIM(A25), FIND(" ",TRIM(A25))-1),MID(TRIM(A25),LEN(C25)+3,FIND(" ",TRIM(A25)&" ",LEN(C25)+3)-LEN(C25)-2)) -> Dhanya | D25: =IF(ISERROR(FIND(",",TRIM(A25))),IF(LEN(TRIM(A25))-LEN(SUBSTITUTE(TRIM(A25)," ",""))=2,MID(TRIM(A25),LEN(C25)+2,FIND(" ",TRIM(A25),LEN(C25)+2)-LEN(C25)-2),""),MID(TRIM(A25),3+LEN(C25)+LEN(E25),30)) | E25: =IF(ISERROR(FIND(",",TRIM(A25))),MID(TRIM(A25),1+LEN(TRIM(A25))-LEN(SUBSTITUTE(TRIM(A25)," ",""))+LEN(C25)+LEN(D25),30),LEFT(TRIM(A25), FIND(",",TRIM(A25))-1)) -> Bhola | F25: D- anya
A26: Amelia Jane Borawski | C26: =IF(ISERROR( FIND(",",TRIM(A26))),LEFT(TRIM(A26), FIND(" ",TRIM(A26))-1),MID(TRIM(A26),LEN(C26)+3,FIND(" ",TRIM(A26)&" ",LEN(C26)+3)-LEN(C26)-2)) -> Amelia | D26: =IF(ISERROR(FIND(",",TRIM(A26))),IF(LEN(TRIM(A26))-LEN(SUBSTITUTE(TRIM(A26)," ",""))=2,MID(TRIM(A26),LEN(C26)+2,FIND(" ",TRIM(A26),LEN(C26)+2)-LEN(C26)-2),""),MID(TRIM(A26),3+LEN(C26)+LEN(E26),30)) -> Jane | E26: =IF(ISERROR(FIND(",",TRIM(A26))),MID(TRIM(A26),1+LEN(TRIM(A26))-LEN(SUBSTITUTE(TRIM(A26)," ",""))+LEN(C26)+LEN(D26),30),LEFT(TRIM(A26), FIND(",",TRIM(A26))-1)) -> Borawski
A27: Elizabeth Boucher | C27: =IF(ISERROR( FIND(",",TRIM(A27))),LEFT(TRIM(A27), FIND(" ",TRIM(A27))-1),MID(TRIM(A27),LEN(C27)+3,FIND(" ",TRIM(A27)&" ",LEN(C27)+3)-LEN(C27)-2)) -> Elizabeth | D27: =IF(ISERROR(FIND(",",TRIM(A27))),IF(LEN(TRIM(A27))-LEN(SUBSTITUTE(TRIM(A27)," ",""))=2,MID(TRIM(A27),LEN(C27)+2,FIND(" ",TRIM(A27),LEN(C27)+2)-LEN(C27)-2),""),MID(TRIM(A27),3+LEN(C27)+LEN(E27),30)) | E27: =IF(ISERROR(FIND(",",TRIM(A27))),MID(TRIM(A27),1+LEN(TRIM(A27))-LEN(SUBSTITUTE(TRIM(A27)," ",""))+LEN(C27)+LEN(D27),30),LEFT(TRIM(A27), FIND(",",TRIM(A27))-1)) -> Boucher | F27: BOO-SHAY
A28: Danielle Bowers | C28: =IF(ISERROR( FIND(",",TRIM(A28))),LEFT(TRIM(A28), FIND(" ",TRIM(A28))-1),MID(TRIM(A28),LEN(C28)+3,FIND(" ",TRIM(A28)&" ",LEN(C28)+3)-LEN(C28)-2)) -> Danielle | D28: =IF(ISERROR(FIND(",",TRIM(A28))),IF(LEN(TRIM(A28))-LEN(SUBSTITUTE(TRIM(A28)," ",""))=2,MID(TRIM(A28),LEN(C28)+2,FIND(" ",TRIM(A28),LEN(C28)+2)-LEN(C28)-2),""),MID(TRIM(A28),3+LEN(C28)+LEN(E28),30)) | E28: =IF(ISERROR(FIND(",",TRIM(A28))),MID(TRIM(A28),1+LEN(TRIM(A28))-LEN(SUBSTITUTE(TRIM(A28)," ",""))+LEN(C28)+LEN(D28),30),LEFT(TRIM(A28), FIND(",",TRIM(A28))-1)) -> Bowers
A29: Lucas Bowlin | C29: =IF(ISERROR( FIND(",",TRIM(A29))),LEFT(TRIM(A29), FIND(" ",TRIM(A29))-1),MID(TRIM(A29),LEN(C29)+3,FIND(" ",TRIM(A29)&" ",LEN(C29)+3)-LEN(C29)-2)) -> Lucas | D29: =IF(ISERROR(FIND(",",TRIM(A29))),IF(LEN(TRIM(A29))-LEN(SUBSTITUTE(TRIM(A29)," ",""))=2,MID(TRIM(A29),LEN(C29)+2,FIND(" ",TRIM(A29),LEN(C29)+2)-LEN(C29)-2),""),MID(TRIM(A29),3+LEN(C29)+LEN(E29),30)) | E29: =IF(ISERROR(FIND(",",TRIM(A29))),MID(TRIM(A29),1+LEN(TRIM(A29))-LEN(SUBSTITUTE(TRIM(A29)," ",""))+LEN(C29)+LEN(D29),30),LEFT(TRIM(A29), FIND(",",TRIM(A29))-1)) -> Bowlin | F29: bohl-in
A30: Indigo Boyko | C30: =IF(ISERROR( FIND(",",TRIM(A30))),LEFT(TRIM(A30), FIND(" ",TRIM(A30))-1),MID(TRIM(A30),LEN(C30)+3,FIND(" ",TRIM(A30)&" ",LEN(C30)+3)-LEN(C30)-2)) -> Indigo | D30: =IF(ISERROR(FIND(",",TRIM(A30))),IF(LEN(TRIM(A30))-LEN(SUBSTITUTE(TRIM(A30)," ",""))=2,MID(TRIM(A30),LEN(C30)+2,FIND(" ",TRIM(A30),LEN(C30)+2)-LEN(C30)-2),""),MID(TRIM(A30),3+LEN(C30)+LEN(E30),30)) | E30: =IF(ISERROR(FIND(",",TRIM(A30))),MID(TRIM(A30),1+LEN(TRIM(A30))-LEN(SUBSTITUTE(TRIM(A30)," ",""))+LEN(C30)+LEN(D30),30),LEFT(TRIM(A30), FIND(",",TRIM(A30))-1)) -> Boyko
A31: Kaleb Brady | C31: =IF(ISERROR( FIND(",",TRIM(A31))),LEFT(TRIM(A31), FIND(" ",TRIM(A31))-1),MID(TRIM(A31),LEN(C31)+3,FIND(" ",TRIM(A31)&" ",LEN(C31)+3)-LEN(C31)-2)) -> Kaleb | D31: =IF(ISERROR(FIND(",",TRIM(A31))),IF(LEN(TRIM(A31))-LEN(SUBSTITUTE(TRIM(A31)," ",""))=2,MID(TRIM(A31),LEN(C31)+2,FIND(" ",TRIM(A31),LEN(C31)+2)-LEN(C31)-2),""),MID(TRIM(A31),3+LEN(C31)+LEN(E31),30)) | E31: =IF(ISERROR(FIND(",",TRIM(A31))),MID(TRIM(A31),1+LEN(TRIM(A31))-LEN(SUBSTITUTE(TRIM(A31)," ",""))+LEN(C31)+LEN(D31),30),LEFT(TRIM(A31), FIND(",",TRIM(A31))-1)) -> Brady
A32: A.J. Bramante | C32: =IF(ISERROR( FIND(",",TRIM(A32))),LEFT(TRIM(A32), FIND(" ",TRIM(A32))-1),MID(TRIM(A32),LEN(C32)+3,FIND(" ",TRIM(A32)&" ",LEN(C32)+3)-LEN(C32)-2)) -> A.J. | D32: =IF(ISERROR(FIND(",",TRIM(A32))),IF(LEN(TRIM(A32))-LEN(SUBSTITUTE(TRIM(A32)," ",""))=2,MID(TRIM(A32),LEN(C32)+2,FIND(" ",TRIM(A32),LEN(C32)+2)-LEN(C32)-2),""),MID(TRIM(A32),3+LEN(C32)+LEN(E32),30)) | E32: =IF(ISERROR(FIND(",",TRIM(A32))),MID(TRIM(A32),1+LEN(TRIM(A32))-LEN(SUBSTITUTE(TRIM(A32)," ",""))+LEN(C32)+LEN(D32),30),LEFT(TRIM(A32), FIND(",",TRIM(A32))-1)) -> Bramante
A33: Ashley Brown | C33: =IF(ISERROR( FIND(",",TRIM(A33))),LEFT(TRIM(A33), FIND(" ",TRIM(A33))-1),MID(TRIM(A33),LEN(C33)+3,FIND(" ",TRIM(A33)&" ",LEN(C33)+3)-LEN(C33)-2)) -> Ashley | D33: =IF(ISERROR(FIND(",",TRIM(A33))),IF(LEN(TRIM(A33))-LEN(SUBSTITUTE(TRIM(A33)," ",""))=2,MID(TRIM(A33),LEN(C33)+2,FIND(" ",TRIM(A33),LEN(C33)+2)-LEN(C33)-2),""),MID(TRIM(A33),3+LEN(C33)+LEN(E33),30)) | E33: =IF(ISERROR(FIND(",",TRIM(A33))),MID(TRIM(A33),1+LEN(TRIM(A33))-LEN(SUBSTITUTE(TRIM(A33)," ",""))+LEN(C33)+LEN(D33),30),LEFT(TRIM(A33), FIND(",",TRIM(A33))-1)) -> Brown
A34: Elijah Brown | C34: =IF(ISERROR( FIND(",",TRIM(A34))),LEFT(TRIM(A34), FIND(" ",TRIM(A34))-1),MID(TRIM(A34),LEN(C34)+3,FIND(" ",TRIM(A34)&" ",LEN(C34)+3)-LEN(C34)-2)) -> Elijah | D34: =IF(ISERROR(FIND(",",TRIM(A34))),IF(LEN(TRIM(A34))-LEN(SUBSTITUTE(TRIM(A34)," ",""))=2,MID(TRIM(A34),LEN(C34)+2,FIND(" ",TRIM(A34),LEN(C34)+2)-LEN(C34)-2),""),MID(TRIM(A34),3+LEN(C34)+LEN(E34),30)) | E34: =IF(ISERROR(FIND(",",TRIM(A34))),MID(TRIM(A34),1+LEN(TRIM(A34))-LEN(SUBSTITUTE(TRIM(A34)," ",""))+LEN(C34)+LEN(D34),30),LEFT(TRIM(A34), FIND(",",TRIM(A34))-1)) -> Brown
A35: Luke Anthony Bunker (not eligible not walking, not in program) | C35: =IF(ISERROR( FIND(",",TRIM(A35))),LEFT(TRIM(A35), FIND(" ",TRIM(A35))-1),MID(TRIM(A35),LEN(C35)+3,FIND(" ",TRIM(A35)&" ",LEN(C35)+3)-LEN(C35)-2)) -> Devyn | D35: =IF(ISERROR(FIND(",",TRIM(A35))),IF(LEN(TRIM(A35))-LEN(SUBSTITUTE(TRIM(A35)," ",""))=2,MID(TRIM(A35),LEN(C35)+2,FIND(" ",TRIM(A35),LEN(C35)+2)-LEN(C35)-2),""),MID(TRIM(A35),3+LEN(C35)+LEN(E35),30)) | E35: =IF(ISERROR(FIND(",",TRIM(A35))),MID(TRIM(A35),1+LEN(TRIM(A35))-LEN(SUBSTITUTE(TRIM(A35)," ",""))+LEN(C35)+LEN(D35),30),LEFT(TRIM(A35), FIND(",",TRIM(A35))-1)) -> Luke Anthony Bunker (not eligible not walking
A36: Braeden Callan | C36: =IF(ISERROR( FIND(",",TRIM(A36))),LEFT(TRIM(A36), FIND(" ",TRIM(A36))-1),MID(TRIM(A36),LEN(C36)+3,FIND(" ",TRIM(A36)&" ",LEN(C36)+3)-LEN(C36)-2)) -> Braeden | D36: =IF(ISERROR(FIND(",",TRIM(A36))),IF(LEN(TRIM(A36))-LEN(SUBSTITUTE(TRIM(A36)," ",""))=2,MID(TRIM(A36),LEN(C36)+2,FIND(" ",TRIM(A36),LEN(C36)+2)-LEN(C36)-2),""),MID(TRIM(A36),3+LEN(C36)+LEN(E36),30)) | E36: =IF(ISERROR(FIND(",",TRIM(A36))),MID(TRIM(A36),1+LEN(TRIM(A36))-LEN(SUBSTITUTE(TRIM(A36)," ",""))+LEN(C36)+LEN(D36),30),LEFT(TRIM(A36), FIND(",",TRIM(A36))-1)) -> Callan
A37: Nilton Campos | C37: =IF(ISERROR( FIND(",",TRIM(A37))),LEFT(TRIM(A37), FIND(" ",TRIM(A37))-1),MID(TRIM(A37),LEN(C37)+3,FIND(" ",TRIM(A37)&" ",LEN(C37)+3)-LEN(C37)-2)) -> Nilton | D37: =IF(ISERROR(FIND(",",TRIM(A37))),IF(LEN(TRIM(A37))-LEN(SUBSTITUTE(TRIM(A37)," ",""))=2,MID(TRIM(A37),LEN(C37)+2,FIND(" ",TRIM(A37),LEN(C37)+2)-LEN(C37)-2),""),MID(TRIM(A37),3+LEN(C37)+LEN(E37),30)) | E37: =IF(ISERROR(FIND(",",TRIM(A37))),MID(TRIM(A37),1+LEN(TRIM(A37))-LEN(SUBSTITUTE(TRIM(A37)," ",""))+LEN(C37)+LEN(D37),30),LEFT(TRIM(A37), FIND(",",TRIM(A37))-1)) -> Campos
A38: Ethan Cannon | C38: =IF(ISERROR( FIND(",",TRIM(A38))),LEFT(TRIM(A38), FIND(" ",TRIM(A38))-1),MID(TRIM(A38),LEN(C38)+3,FIND(" ",TRIM(A38)&" ",LEN(C38)+3)-LEN(C38)-2)) -> Ethan | D38: =IF(ISERROR(FIND(",",TRIM(A38))),IF(LEN(TRIM(A38))-LEN(SUBSTITUTE(TRIM(A38)," ",""))=2,MID(TRIM(A38),LEN(C38)+2,FIND(" ",TRIM(A38),LEN(C38)+2)-LEN(C38)-2),""),MID(TRIM(A38),3+LEN(C38)+LEN(E38),30)) | E38: =IF(ISERROR(FIND(",",TRIM(A38))),MID(TRIM(A38),1+LEN(TRIM(A38))-LEN(SUBSTITUTE(TRIM(A38)," ",""))+LEN(C38)+LEN(D38),30),LEFT(TRIM(A38), FIND(",",TRIM(A38))-1)) -> Cannon
A39: Lucas Carcione | C39: =IF(ISERROR( FIND(",",TRIM(A39))),LEFT(TRIM(A39), FIND(" ",TRIM(A39))-1),MID(TRIM(A39),LEN(C39)+3,FIND(" ",TRIM(A39)&" ",LEN(C39)+3)-LEN(C39)-2)) -> Lucas | D39: =IF(ISERROR(FIND(",",TRIM(A39))),IF(LEN(TRIM(A39))-LEN(SUBSTITUTE(TRIM(A39)," ",""))=2,MID(TRIM(A39),LEN(C39)+2,FIND(" ",TRIM(A39),LEN(C39)+2)-LEN(C39)-2),""),MID(TRIM(A39),3+LEN(C39)+LEN(E39),30)) | E39: =IF(ISERROR(FIND(",",TRIM(A39))),MID(TRIM(A39),1+LEN(TRIM(A39))-LEN(SUBSTITUTE(TRIM(A39)," ",""))+LEN(C39)+LEN(D39),30),LEFT(TRIM(A39), FIND(",",TRIM(A39))-1)) -> Carcione | F39: Car-See-O-Nee
A40: Nicholas Joseph Casarano | C40: =IF(ISERROR( FIND(",",TRIM(A40))),LEFT(TRIM(A40), FIND(" ",TRIM(A40))-1),MID(TRIM(A40),LEN(C40)+3,FIND(" ",TRIM(A40)&" ",LEN(C40)+3)-LEN(C40)-2)) -> Nicholas | D40: =IF(ISERROR(FIND(",",TRIM(A40))),IF(LEN(TRIM(A40))-LEN(SUBSTITUTE(TRIM(A40)," ",""))=2,MID(TRIM(A40),LEN(C40)+2,FIND(" ",TRIM(A40),LEN(C40)+2)-LEN(C40)-2),""),MID(TRIM(A40),3+LEN(C40)+LEN(E40),30)) -> Joseph | E40: =IF(ISERROR(FIND(",",TRIM(A40))),MID(TRIM(A40),1+LEN(TRIM(A40))-LEN(SUBSTITUTE(TRIM(A40)," ",""))+LEN(C40)+LEN(D40),30),LEFT(TRIM(A40), FIND(",",TRIM(A40))-1)) -> Casarano
...

Sheet Names with Seat Code
A1: Grad Code | B1: CD Code | C1: First Name | D1: Middle | E1: Last Name | H1: Formal Name | I1: Honor
A2: 1 | B2: 1 | C2: ='Raw Name Splitter'!C2 -> Jillian | D2: ='Raw Name Splitter'!D2 -> Kate | E2: ='Raw Name Splitter'!E2 -> Abate | F2: ='Raw Name Splitter'!F2 -> a-bod-ee | L2: Directions
A3: =IF(ISTEXT(A2)=TRUE,1,2) -> 2 | B3: =IF(ISTEXT(B2)=TRUE,1,2) -> 2 | C3: ='Raw Name Splitter'!C3 -> Logan | D3: ='Raw Name Splitter'!D3 -> Ford | E3: ='Raw Name Splitter'!E3 -> Abrams | F3: ='Raw Name Splitter'!F3 -> 0 | L3: 1. Paste Formal Name and honor in columns H amd I
A4: =IF(ISTEXT(A3)=TRUE,A2+1,A3+1) -> 3 | B4: =IF(ISTEXT(B3)=TRUE,B2+1,B3+1) -> 3 | C4: ='Raw Name Splitter'!C4 -> Raniya | D4: ='Raw Name Splitter'!D4 | E4: ='Raw Name Splitter'!E4 -> Abubakar | F4: ='Raw Name Splitter'!F4 -> Raw-knee-yuh Uh-boo-buh-ker | L4: 2. Shift H and I up/down to match the names in C to F
A5: =IF(ISTEXT(A4)=TRUE,A3+1,A4+1) -> 4 | B5: =IF(ISTEXT(B4)=TRUE,B3+1,B4+1) -> 4 | C5: ='Raw Name Splitter'!C5 -> Luis | D5: ='Raw Name Splitter'!D5 | E5: ='Raw Name Splitter'!E5 -> Aburto Campos | F5: ='Raw Name Splitter'!F5 -> Lou eese Aburto Campos | L5: 3. Add codes
A6: =IF(ISTEXT(A5)=TRUE,A4+1,A5+1) -> 5 | B6: =IF(ISTEXT(B5)=TRUE,IF(ISTEXT(B4)=TRUE,B3+1,B4+1),B5+1) -> 5 | C6: ='Raw Name Splitter'!C6 -> Devyn | D6: ='Raw Name Splitter'!D6 | E6: ='Raw Name Splitter'!E6 -> Ahlert | F6: ='Raw Name Splitter'!F6 -> Dev-in AL-ert
A7: =IF(ISTEXT(A6)=TRUE,A5+1,A6+1) -> 6 | B7: =IF(ISTEXT(B6)=TRUE,IF(ISTEXT(B5)=TRUE,B4+1,B5+1),B6+1) -> 6 | C7: ='Raw Name Splitter'!C7 -> Alexander | D7: ='Raw Name Splitter'!D7 | E7: ='Raw Name Splitter'!E7 -> Aiello | F7: ='Raw Name Splitter'!F7 -> Aiello (I-L-O) | L7: Codes
A8: =IF(ISTEXT(A7)=TRUE,IF(ISTEXT(A6)=TRUE,A5+1,A6+1),A7+1) -> 7 | B8: =IF(ISTEXT(B7)=TRUE,IF(ISTEXT(B6)=TRUE,B5+1,B6+1),B7+1) -> 7 | C8: ='Raw Name Splitter'!C8 -> Reese | D8: ='Raw Name Splitter'!D8 | E8: ='Raw Name Splitter'!E8 -> Allen | F8: ='Raw Name Splitter'!F8 -> Reese Allen | L8: val | M8: valedictorian
A9: =IF(ISTEXT(A8)=TRUE,IF(ISTEXT(A7)=TRUE,A6+1,A7+1),A8+1) -> 8 | B9: =IF(ISTEXT(B8)=TRUE,IF(ISTEXT(B7)=TRUE,B6+1,B7+1),B8+1) -> 8 | C9: ='Raw Name Splitter'!C9 -> Fabricio | D9: ='Raw Name Splitter'!D9 | E9: ='Raw Name Splitter'!E9 -> Amado | F9: ='Raw Name Splitter'!F9 -> Fah-bree-cee-oh Ah-mod-oh | L9: v2 | M9: use in case of tie for val or sal
A10: =IF(ISTEXT(A9)=TRUE,IF(ISTEXT(A8)=TRUE,A7+1,A8+1),A9+1) -> 9 | B10: =IF(ISTEXT(B9)=TRUE,IF(ISTEXT(B8)=TRUE,B7+1,B8+1),B9+1) -> 9 | C10: ='Raw Name Splitter'!C10 -> Joseph | D10: ='Raw Name Splitter'!D10 | E10: ='Raw Name Splitter'!E10 -> Amirault | F10: ='Raw Name Splitter'!F10 -> 0 | L10: sal | M10: salutorian
A11: =IF(ISTEXT(A10)=TRUE,IF(ISTEXT(A9)=TRUE,A8+1,A9+1),A10+1) -> 10 | B11: =IF(ISTEXT(B10)=TRUE,IF(ISTEXT(B9)=TRUE,B8+1,B9+1),B10+1) -> 10 | C11: ='Raw Name Splitter'!C11 -> Brady | D11: ='Raw Name Splitter'!D11 | E11: ='Raw Name Splitter'!E11 -> Anderson | F11: ='Raw Name Splitter'!F11 -> 0 | L11: scp | M11: student council president
A12: =IF(ISTEXT(A11)=TRUE,IF(ISTEXT(A10)=TRUE,A9+1,A10+1),A11+1) -> 11 | B12: =IF(ISTEXT(B11)=TRUE,IF(ISTEXT(B10)=TRUE,B9+1,B10+1),B11+1) -> 11 | C12: ='Raw Name Splitter'!C12 -> Barrington | D12: ='Raw Name Splitter'!D12 | E12: ='Raw Name Splitter'!E12 -> Anderson | F12: ='Raw Name Splitter'!F12 -> 0 | L12: cp | M12: class president
A13: =IF(ISTEXT(A12)=TRUE,IF(ISTEXT(A11)=TRUE,A10+1,A11+1),A12+1) -> 12 | B13: =IF(ISTEXT(B12)=TRUE,IF(ISTEXT(B11)=TRUE,B10+1,B11+1),B12+1) -> 12 | C13: ='Raw Name Splitter'!C13 -> Isabella | D13: ='Raw Name Splitter'!D13 | E13: ='Raw Name Splitter'!E13 -> Aquino | F13: ='Raw Name Splitter'!F13 -> Isabell-uh Ah-kee-no | L13: c1 | M13: class officer 1 - usual vp
A14: =IF(ISTEXT(A13)=TRUE,IF(ISTEXT(A12)=TRUE,A11+1,A12+1),A13+1) -> 13 | B14: =IF(ISTEXT(B13)=TRUE,IF(ISTEXT(B12)=TRUE,B11+1,B12+1),B13+1) -> 13 | C14: ='Raw Name Splitter'!C14 -> Lucas | D14: ='Raw Name Splitter'!D14 | E14: ='Raw Name Splitter'!E14 -> Aquino | F14: ='Raw Name Splitter'!F14 -> 0 | L14: c2 | M14: class officer 2 - usual treasurer
A15: =IF(ISTEXT(A14)=TRUE,IF(ISTEXT(A13)=TRUE,A12+1,A13+1),A14+1) -> 14 | B15: =IF(ISTEXT(B14)=TRUE,IF(ISTEXT(B13)=TRUE,B12+1,B13+1),B14+1) -> 14 | C15: ='Raw Name Splitter'!C15 -> Tiago | D15: ='Raw Name Splitter'!D15 | E15: ='Raw Name Splitter'!E15 -> Araujo | F15: ='Raw Name Splitter'!F15 -> TEE-ah-go AH-ra-joe | L15: c3 | M15: class officer 3 - usually secretary
A16: =IF(ISTEXT(A15)=TRUE,IF(ISTEXT(A14)=TRUE,A13+1,A14+1),A15+1) -> 15 | B16: =IF(ISTEXT(B15)=TRUE,IF(ISTEXT(B14)=TRUE,B13+1,B14+1),B15+1) -> 15 | C16: ='Raw Name Splitter'!C16 -> Chloe | D16: ='Raw Name Splitter'!D16 | E16: ='Raw Name Splitter'!E16 -> Aretusi | F16: ='Raw Name Splitter'!F16 -> ah-reh-toozy | L16: c4 | M16: class officer
A17: =IF(ISTEXT(A16)=TRUE,IF(ISTEXT(A15)=TRUE,A14+1,A15+1),A16+1) -> 16 | B17: =IF(ISTEXT(B16)=TRUE,IF(ISTEXT(B15)=TRUE,B14+1,B15+1),B16+1) -> 16 | C17: ='Raw Name Splitter'!C17 -> Evan | D17: ='Raw Name Splitter'!D17 | E17: ='Raw Name Splitter'!E17 -> Audley | F17: ='Raw Name Splitter'!F17 -> 0 | L17: c5 | M17: class officer
A18: =IF(ISTEXT(A17)=TRUE,IF(ISTEXT(A16)=TRUE,A15+1,A16+1),A17+1) -> 17 | B18: =IF(ISTEXT(B17)=TRUE,IF(ISTEXT(B16)=TRUE,B15+1,B16+1),B17+1) -> 17 | C18: ='Raw Name Splitter'!C18 -> Natalie | D18: ='Raw Name Splitter'!D18 | E18: ='Raw Name Splitter'!E18 -> Austin | F18: ='Raw Name Splitter'!F18 -> 0 | L18: c6 | M18: class officer
A19: =IF(ISTEXT(A18)=TRUE,IF(ISTEXT(A17)=TRUE,A16+1,A17+1),A18+1) -> 18 | B19: =IF(ISTEXT(B18)=TRUE,IF(ISTEXT(B17)=TRUE,B16+1,B17+1),B18+1) -> 18 | C19: ='Raw Name Splitter'!C19 -> Vivian | D19: ='Raw Name Splitter'!D19 | E19: ='Raw Name Splitter'!E19 -> Balas | F19: ='Raw Name Splitter'!F19 -> 0 | L19: c7 | M19: class officer
... A24: =IF(ISTEXT(A23)=TRUE,IF(ISTEXT(A22)=TRUE,A21+1,A22+1),A23+1) -> 23 | B24: =IF(ISTEXT(B23)=TRUE,IF(ISTEXT(B22)=TRUE,B21+1,B22+1),B23+1) -> 23 | C24: ='Raw Name Splitter'!C24 -> Jamison | D24: ='Raw Name Splitter'!D24 | E24: ='Raw Name Splitter'!E24 -> Bentley | F24: ='Raw Name Splitter'!F24 -> 0 | L24: x | M24: student is not walking
A25: =IF(ISTEXT(A24)=TRUE,IF(ISTEXT(A23)=TRUE,A22+1,A23+1),A24+1) -> 24 | B25: =IF(ISTEXT(B24)=TRUE,IF(ISTEXT(B23)=TRUE,B22+1,B23+1),B24+1) -> 24 | C25: ='Raw Name Splitter'!C25 -> Dhanya | D25: ='Raw Name Splitter'!D25 | E25: ='Raw Name Splitter'!E25 -> Bhola | F25: ='Raw Name Splitter'!F25 -> D- anya
A26: val | B26: val | C26: ='Raw Name Splitter'!C26 -> Amelia | D26: ='Raw Name Splitter'!D26 -> Jane | E26: ='Raw Name Splitter'!E26 -> Borawski | F26: ='Raw Name Splitter'!F26 -> 0
A27: =IF(ISTEXT(A26)=TRUE,IF(ISTEXT(A25)=TRUE,A24+1,A25+1),A26+1) -> 25 | B27: =IF(ISTEXT(B26)=TRUE,IF(ISTEXT(B25)=TRUE,B24+1,B25+1),B26+1) -> 25 | C27: ='Raw Name Splitter'!C27 -> Elizabeth | D27: ='Raw Name Splitter'!D27 | E27: ='Raw Name Splitter'!E27 -> Boucher | F27: ='Raw Name Splitter'!F27 -> BOO-SHAY
A28: =IF(ISTEXT(A27)=TRUE,IF(ISTEXT(A26)=TRUE,A25+1,A26+1),A27+1) -> 26 | B28: =IF(ISTEXT(B27)=TRUE,IF(ISTEXT(B26)=TRUE,B25+1,B26+1),B27+1) -> 26 | C28: ='Raw Name Splitter'!C28 -> Danielle | D28: ='Raw Name Splitter'!D28 | E28: ='Raw Name Splitter'!E28 -> Bowers | F28: ='Raw Name Splitter'!F28 -> 0
A29: =IF(ISTEXT(A28)=TRUE,IF(ISTEXT(A27)=TRUE,A26+1,A27+1),A28+1) -> 27 | B29: =IF(ISTEXT(B28)=TRUE,IF(ISTEXT(B27)=TRUE,B26+1,B27+1),B28+1) -> 27 | C29: ='Raw Name Splitter'!C29 -> Lucas | D29: ='Raw Name Splitter'!D29 | E29: ='Raw Name Splitter'!E29 -> Bowlin | F29: ='Raw Name Splitter'!F29 -> bohl-in
A30: sal | B30: sal | C30: ='Raw Name Splitter'!C30 -> Indigo | D30: ='Raw Name Splitter'!D30 | E30: ='Raw Name Splitter'!E30 -> Boyko | F30: ='Raw Name Splitter'!F30 -> 0
A31: =IF(ISTEXT(A30)=TRUE,IF(ISTEXT(A29)=TRUE,A28+1,A29+1),A30+1) -> 28 | B31: =IF(ISTEXT(B30)=TRUE,IF(ISTEXT(B29)=TRUE,B28+1,B29+1),B30+1) -> 28 | C31: ='Raw Name Splitter'!C31 -> Kaleb | D31: ='Raw Name Splitter'!D31 | E31: ='Raw Name Splitter'!E31 -> Brady | F31: ='Raw Name Splitter'!F31 -> 0
A32: =IF(ISTEXT(A31)=TRUE,IF(ISTEXT(A30)=TRUE,A29+1,A30+1),A31+1) -> 29 | B32: =IF(ISTEXT(B31)=TRUE,IF(ISTEXT(B30)=TRUE,B29+1,B30+1),B31+1) -> 29 | C32: ='Raw Name Splitter'!C32 -> A.J. | D32: ='Raw Name Splitter'!D32 | E32: ='Raw Name Splitter'!E32 -> Bramante
A33: =IF(ISTEXT(A32)=TRUE,IF(ISTEXT(A31)=TRUE,A30+1,A31+1),A32+1) -> 30 | B33: =IF(ISTEXT(B32)=TRUE,IF(ISTEXT(B31)=TRUE,B30+1,B31+1),B32+1) -> 30 | C33: ='Raw Name Splitter'!C33 -> Ashley | D33: ='Raw Name Splitter'!D33 | E33: ='Raw Name Splitter'!E33 -> Brown | F33: ='Raw Name Splitter'!F33 -> 0
A34: =IF(ISTEXT(A33)=TRUE,IF(ISTEXT(A32)=TRUE,A31+1,A32+1),A33+1) -> 31 | B34: =IF(ISTEXT(B33)=TRUE,IF(ISTEXT(B32)=TRUE,B31+1,B32+1),B33+1) -> 31 | C34: ='Raw Name Splitter'!C34 -> Elijah | D34: ='Raw Name Splitter'!D34 | E34: ='Raw Name Splitter'!E34 -> Brown | F34: ='Raw Name Splitter'!F34 -> 0
A35: x | B35: x | C35: ='Raw Name Splitter'!C35 -> Joseph | D35: ='Raw Name Splitter'!D35 | E35: ='Raw Name Splitter'!E35 -> Luke Anthony Bunker (not eligible not walking | F35: ='Raw Name Splitter'!F35 -> 0
A36: =IF(ISTEXT(A35)=TRUE,IF(ISTEXT(A34)=TRUE,A33+1,A34+1),A35+1) -> 32 | B36: =IF(ISTEXT(B35)=TRUE,IF(ISTEXT(B34)=TRUE,B33+1,B34+1),B35+1) -> 32 | C36: ='Raw Name Splitter'!C36 -> Braeden | D36: ='Raw Name Splitter'!D36 | E36: ='Raw Name Splitter'!E36 -> Callan | F36: ='Raw Name Splitter'!F36 -> 0
A37: =IF(ISTEXT(A36)=TRUE,IF(ISTEXT(A35)=TRUE,A34+1,A35+1),A36+1) -> 33 | B37: =IF(ISTEXT(B36)=TRUE,IF(ISTEXT(B35)=TRUE,B34+1,B35+1),B36+1) -> 33 | C37: ='Raw Name Splitter'!C37 -> Nilton | D37: ='Raw Name Splitter'!D37 | E37: ='Raw Name Splitter'!E37 -> Campos | F37: ='Raw Name Splitter'!F37 -> 0
A38: =IF(ISTEXT(A37)=TRUE,IF(ISTEXT(A36)=TRUE,A35+1,A36+1),A37+1) -> 34 | B38: =IF(ISTEXT(B37)=TRUE,IF(ISTEXT(B36)=TRUE,B35+1,B36+1),B37+1) -> 34 | C38: ='Raw Name Splitter'!C38 -> Ethan | D38: ='Raw Name Splitter'!D38 | E38: ='Raw Name Splitter'!E38 -> Cannon | F38: ='Raw Name Splitter'!F38 -> 0
A39: =IF(ISTEXT(A38)=TRUE,IF(ISTEXT(A37)=TRUE,A36+1,A37+1),A38+1) -> 35 | B39: =IF(ISTEXT(B38)=TRUE,IF(ISTEXT(B37)=TRUE,B36+1,B37+1),B38+1) -> 35 | C39: ='Raw Name Splitter'!C39 -> Lucas | D39: ='Raw Name Splitter'!D39 | E39: ='Raw Name Splitter'!E39 -> Carcione | F39: ='Raw Name Splitter'!F39 -> Car-See-O-Nee
A40: =IF(ISTEXT(A39)=TRUE,IF(ISTEXT(A38)=TRUE,A37+1,A38+1),A39+1) -> 36 | B40: =IF(ISTEXT(B39)=TRUE,IF(ISTEXT(B38)=TRUE,B37+1,B38+1),B39+1) -> 36 | C40: ='Raw Name Splitter'!C40 -> Nicholas | D40: ='Raw Name Splitter'!D40 -> Joseph | E40: ='Raw Name Splitter'!E40 -> Casarano | F40: ='Raw Name Splitter'!F40 -> 0
A41: =IF(ISTEXT(A40)=TRUE,IF(ISTEXT(A39)=TRUE,A38+1,A39+1),A40+1) -> 37 | B41: =IF(ISTEXT(B40)=TRUE,IF(ISTEXT(B39)=TRUE,B38+1,B39+1),B40+1) -> 37 | C41: ='Raw Name Splitter'!C41 -> Maggie | D41: ='Raw Name Splitter'!D41 | E41: ='Raw Name Splitter'!E41 -> Champlin-Scharff | F41: ='Raw Name Splitter'!F41 -> 0
A42: =IF(ISTEXT(A41)=TRUE,IF(ISTEXT(A40)=TRUE,A39+1,A40+1),A41+1) -> 38 | B42: =IF(ISTEXT(B41)=TRUE,IF(ISTEXT(B40)=TRUE,B39+1,B40+1),B41+1) -> 38 | C42: ='Raw Name Splitter'!C42 -> Elsa | D42: ='Raw Name Splitter'!D42 | E42: ='Raw Name Splitter'!E42 -> Chow | F42: ='Raw Name Splitter'!F42 -> 0
A43: =IF(ISTEXT(A42)=TRUE,IF(ISTEXT(A41)=TRUE,A40+1,A41+1),A42+1) -> 39 | B43: =IF(ISTEXT(B42)=TRUE,IF(ISTEXT(B41)=TRUE,B40+1,B41+1),B42+1) -> 39 | C43: ='Raw Name Splitter'!C43 -> Will | D43: ='Raw Name Splitter'!D43 | E43: ='Raw Name Splitter'!E43 -> Chute | F43: ='Raw Name Splitter'!F43 -> 0
A44: =IF(ISTEXT(A43)=TRUE,IF(ISTEXT(A42)=TRUE,A41+1,A42+1),A43+1) -> 40 | B44: =IF(ISTEXT(B43)=TRUE,IF(ISTEXT(B42)=TRUE,B41+1,B42+1),B43+1) -> 40 | C44: ='Raw Name Splitter'!C44 -> Max | D44: ='Raw Name Splitter'!D44 | E44: ='Raw Name Splitter'!E44 -> Cinelli | F44: ='Raw Name Splitter'!F44 -> 0
...

Sheet Grad Raw Data
A1: SECTION | B1: ROW | C1: SEAT NUMBER | D1: SIDE | E1: ROW | F1: SEAT NUMBER | G1: Honor | H1: Last Name | I1: First Name | K1: Middle
A2: STAGE | B2: STAGE | C2: 1 | D2: STAGE | E2: STAGE | F2: v1 | G2: =VLOOKUP(J2,'Names with Seat Code'!A:I,9,FALSE) -> 0 | H2: =VLOOKUP(J2,'Names with Seat Code'!A:E,5,FALSE) -> Borawski | I2: =VLOOKUP(J2,'Names with Seat Code'!A:E,3,FALSE) -> Amelia | J2: val | K2: =VLOOKUP(J2,'Names with Seat Code'!A:E,4,FALSE) -> Jane | L2: =VLOOKUP(J2,'Names with Seat Code'!A:F,6,FALSE) -> 0
A3: STAGE | B3: STAGE | C3: 1 | D3: STAGE | E3: STAGE | F3: v2 | G3: =VLOOKUP(J3,'Names with Seat Code'!A:I,9,FALSE) -> 0 | H3: =VLOOKUP(J3,'Names with Seat Code'!A:E,5,FALSE) -> - | I3: =VLOOKUP(J3,'Names with Seat Code'!A:E,3,FALSE) -> - | J3: v2
A4: STAGE | B4: STAGE | C4: 2 | D4: STAGE | E4: STAGE | F4: sal | G4: =VLOOKUP(J4,'Names with Seat Code'!A:I,9,FALSE) -> 0 | H4: =VLOOKUP(J4,'Names with Seat Code'!A:E,5,FALSE) -> Boyko | I4: =VLOOKUP(J4,'Names with Seat Code'!A:E,3,FALSE) -> Indigo | J4: sal | K4: =VLOOKUP(J4,'Names with Seat Code'!A:E,4,FALSE) | L4: =VLOOKUP(J4,'Names with Seat Code'!A:F,6,FALSE) -> 0
A5: STAGE | B5: STAGE | C5: 3 | D5: STAGE | E5: STAGE | F5: cp | G5: =VLOOKUP(J5,'Names with Seat Code'!A:I,9,FALSE) -> 0 | H5: =VLOOKUP(J5,'Names with Seat Code'!A:E,5,FALSE) -> Walsh | I5: =VLOOKUP(J5,'Names with Seat Code'!A:E,3,FALSE) -> Jason | J5: cp | K5: =VLOOKUP(J5,'Names with Seat Code'!A:E,4,FALSE) | L5: =VLOOKUP(J5,'Names with Seat Code'!A:F,6,FALSE) -> 0
A6: STAGE | B6: STAGE | C6: 4 | D6: STAGE | E6: STAGE | F6: scp | G6: =VLOOKUP(J6,'Names with Seat Code'!A:I,9,FALSE) -> 0 | H6: =VLOOKUP(J6,'Names with Seat Code'!A:E,5,FALSE) -> Wong | I6: =VLOOKUP(J6,'Names with Seat Code'!A:E,3,FALSE) -> Jessica | J6: scp | K6: =VLOOKUP(J6,'Names with Seat Code'!A:E,4,FALSE) | L6: =VLOOKUP(J6,'Names with Seat Code'!A:F,6,FALSE) -> 0
A7: LOWER | B7: A | C7: 101 | D7: RIGHT | E7: 1 | F7: 1 | G7: =VLOOKUP(J7,'Names with Seat Code'!A:I,9,FALSE) -> 0 | H7: =VLOOKUP(J7,'Names with Seat Code'!A:E,5,FALSE) -> Healy | I7: =VLOOKUP(J7,'Names with Seat Code'!A:E,3,FALSE) -> Clara | J7: c1 | K7: =VLOOKUP(J7,'Names with Seat Code'!A:E,4,FALSE) | L7: =VLOOKUP(J7,'Names with Seat Code'!A:F,6,FALSE) -> 0
A8: LOWER | B8: A | C8: 102 | D8: RIGHT | E8: 1 | F8: 2 | G8: =VLOOKUP(J8,'Names with Seat Code'!A:I,9,FALSE) -> 0 | H8: =VLOOKUP(J8,'Names with Seat Code'!A:E,5,FALSE) -> Hillery | I8: =VLOOKUP(J8,'Names with Seat Code'!A:E,3,FALSE) -> Samuel | J8: c2 | K8: =VLOOKUP(J8,'Names with Seat Code'!A:E,4,FALSE) | L8: =VLOOKUP(J8,'Names with Seat Code'!A:F,6,FALSE) -> 0
A9: LOWER | B9: A | C9: 103 | D9: RIGHT | E9: 1 | F9: 3 | G9: =VLOOKUP(J9,'Names with Seat Code'!A:I,9,FALSE) -> 0 | H9: =VLOOKUP(J9,'Names with Seat Code'!A:E,5,FALSE) -> Martin | I9: =VLOOKUP(J9,'Names with Seat Code'!A:E,3,FALSE) -> Piper | J9: c3 | K9: =VLOOKUP(J9,'Names with Seat Code'!A:E,4,FALSE) | L9: =VLOOKUP(J9,'Names with Seat Code'!A:F,6,FALSE) -> 0
A10: LOWER | B10: A | C10: 104 | D10: RIGHT | E10: 1 | F10: 4 | G10: =VLOOKUP(J10,'Names with Seat Code'!A:I,9,FALSE) -> 0 | H10: =VLOOKUP(J10,'Names with Seat Code'!A:E,5,FALSE) -> Mullin | I10: =VLOOKUP(J10,'Names with Seat Code'!A:E,3,FALSE) -> Aidan | J10: c4 | K10: =VLOOKUP(J10,'Names with Seat Code'!A:E,4,FALSE) | L10: =VLOOKUP(J10,'Names with Seat Code'!A:F,6,FALSE) -> Aidan Mullin
A11: LOWER | B11: A | C11: 105 | D11: RIGHT | E11: 1 | F11: 5 | G11: =VLOOKUP(J11,'Names with Seat Code'!A:I,9,FALSE) -> 0 | H11: =VLOOKUP(J11,'Names with Seat Code'!A:E,5,FALSE) -> Nelson | I11: =VLOOKUP(J11,'Names with Seat Code'!A:E,3,FALSE) -> Emma | J11: c5 | K11: =VLOOKUP(J11,'Names with Seat Code'!A:E,4,FALSE) -> Elizabeth | L11: =VLOOKUP(J11,'Names with Seat Code'!A:F,6,FALSE) -> 0
A12: LOWER | B12: A | C12: 106 | D12: RIGHT | E12: 1 | F12: 6 | G12: =VLOOKUP(J12,'Names with Seat Code'!A:I,9,FALSE) -> 0 | H12: =VLOOKUP(J12,'Names with Seat Code'!A:E,5,FALSE) -> Stathoulopoulos | I12: =VLOOKUP(J12,'Names with Seat Code'!A:E,3,FALSE) -> Thomas | J12: c6 | K12: =VLOOKUP(J12,'Names with Seat Code'!A:E,4,FALSE) | L12: =VLOOKUP(J12,'Names with Seat Code'!A:F,6,FALSE) -> Thomas Stath-oh-lop-oh-lus
A13: LOWER | B13: A | C13: 107 | D13: RIGHT | E13: 1 | F13: 7 | G13: =VLOOKUP(J13,'Names with Seat Code'!A:I,9,FALSE) -> 0 | H13: =VLOOKUP(J13,'Names with Seat Code'!A:E,5,FALSE) -> Vitarisi | I13: =VLOOKUP(J13,'Names with Seat Code'!A:E,3,FALSE) -> Cara | J13: c7 | K13: =VLOOKUP(J13,'Names with Seat Code'!A:E,4,FALSE) | L13: =VLOOKUP(J13,'Names with Seat Code'!A:F,6,FALSE) -> 0
A14: LOWER | B14: A | C14: 108 | D14: RIGHT | E14: 1 | F14: 8 | G14: =VLOOKUP(J14,'Names with Seat Code'!A:I,9,FALSE) -> 0 | H14: =VLOOKUP(J14,'Names with Seat Code'!A:E,5,FALSE) -> Abate | I14: =VLOOKUP(J14,'Names with Seat Code'!A:E,3,FALSE) -> Jillian | J14: 1 | K14: =VLOOKUP(J14,'Names with Seat Code'!A:E,4,FALSE) -> Kate | L14: =VLOOKUP(J14,'Names with Seat Code'!A:F,6,FALSE) -> a-bod-ee
A15: LOWER | B15: A | C15: 109 | D15: RIGHT | E15: 1 | F15: 9 | G15: =VLOOKUP(J15,'Names with Seat Code'!A:I,9,FALSE) -> 0 | H15: =VLOOKUP(J15,'Names with Seat Code'!A:E,5,FALSE) -> Abrams | I15: =VLOOKUP(J15,'Names with Seat Code'!A:E,3,FALSE) -> Logan | J15: 2 | K15: =VLOOKUP(J15,'Names with Seat Code'!A:E,4,FALSE) -> Ford
A16: LOWER | B16: A | C16: 110 | D16: RIGHT | E16: 1 | F16: 10 | G16: =VLOOKUP(J16,'Names with Seat Code'!A:I,9,FALSE) -> 0 | H16: =VLOOKUP(J16,'Names with Seat Code'!A:E,5,FALSE) -> Abubakar | I16: =VLOOKUP(J16,'Names with Seat Code'!A:E,3,FALSE) -> Raniya | J16: 3 | K16: =VLOOKUP(J16,'Names with Seat Code'!A:E,4,FALSE)
A17: LOWER | B17: A | C17: 111 | D17: RIGHT | E17: 1 | F17: 11 | G17: =VLOOKUP(J17,'Names with Seat Code'!A:I,9,FALSE) -> 0 | H17: =VLOOKUP(J17,'Names with Seat Code'!A:E,5,FALSE) -> Aburto Campos | I17: =VLOOKUP(J17,'Names with Seat Code'!A:E,3,FALSE) -> Luis | J17: 4 | K17: =VLOOKUP(J17,'Names with Seat Code'!A:E,4,FALSE)
A18: LOWER | B18: A | C18: 112 | D18: RIGHT | E18: 1 | F18: 12 | G18: =VLOOKUP(J18,'Names with Seat Code'!A:I,9,FALSE) -> 0 | H18: =VLOOKUP(J18,'Names with Seat Code'!A:E,5,FALSE) -> Ahlert | I18: =VLOOKUP(J18,'Names with Seat Code'!A:E,3,FALSE) -> Devyn | J18: 5 | K18: =VLOOKUP(J18,'Names with Seat Code'!A:E,4,FALSE) | L18: =VLOOKUP(J18,'Names with Seat Code'!A:F,6,FALSE) -> Dev-in AL-ert
A19: UPPER | B19: O | C19: 122 | D19: LEFT | E19: 1 | F19: 1 | G19: =VLOOKUP(J19,'Names with Seat Code'!A:I,9,FALSE) -> 0 | H19: =VLOOKUP(J19,'Names with Seat Code'!A:E,5,FALSE) -> Aiello | I19: =VLOOKUP(J19,'Names with Seat Code'!A:E,3,FALSE) -> Alexander | J19: 6 | K19: =VLOOKUP(J19,'Names with Seat Code'!A:E,4,FALSE) | L19: =VLOOKUP(J19,'Names with Seat Code'!A:F,6,FALSE) -> Aiello (I-L-O)
A20: UPPER | B20: O | C20: 120 | D20: LEFT | E20: 1 | F20: 2 | G20: =VLOOKUP(J20,'Names with Seat Code'!A:I,9,FALSE) -> 0 | H20: =VLOOKUP(J20,'Names with Seat Code'!A:E,5,FALSE) -> Allen | I20: =VLOOKUP(J20,'Names with Seat Code'!A:E,3,FALSE) -> Reese | J20: 7 | K20: =VLOOKUP(J20,'Names with Seat Code'!A:E,4,FALSE) | L20: =VLOOKUP(J20,'Names with Seat Code'!A:F,6,FALSE) -> Reese Allen
A21: UPPER | B21: O | C21: 118 | D21: LEFT | E21: 1 | F21: 3 | G21: =VLOOKUP(J21,'Names with Seat Code'!A:I,9,FALSE) -> 0 | H21: =VLOOKUP(J21,'Names with Seat Code'!A:E,5,FALSE) -> Amado | I21: =VLOOKUP(J21,'Names with Seat Code'!A:E,3,FALSE) -> Fabricio | J21: 8 | K21: =VLOOKUP(J21,'Names with Seat Code'!A:E,4,FALSE) | L21: =VLOOKUP(J21,'Names with Seat Code'!A:F,6,FALSE) -> Fah-bree-cee-oh Ah-mod-oh
A22: UPPER | B22: O | C22: 116 | D22: LEFT | E22: 1 | F22: 4 | G22: =VLOOKUP(J22,'Names with Seat Code'!A:I,9,FALSE) -> 0 | H22: =VLOOKUP(J22,'Names with Seat Code'!A:E,5,FALSE) -> Amirault | I22: =VLOOKUP(J22,'Names with Seat Code'!A:E,3,FALSE) -> Joseph | J22: 9 | K22: =VLOOKUP(J22,'Names with Seat Code'!A:E,4,FALSE) | L22: =VLOOKUP(J22,'Names with Seat Code'!A:F,6,FALSE) -> 0
A23: UPPER | B23: O | C23: 114 | D23: LEFT | E23: 1 | F23: 5 | G23: =VLOOKUP(J23,'Names with Seat Code'!A:I,9,FALSE) -> 0 | H23: =VLOOKUP(J23,'Names with Seat Code'!A:E,5,FALSE) -> Anderson | I23: =VLOOKUP(J23,'Names with Seat Code'!A:E,3,FALSE) -> Brady | J23: 10 | K23: =VLOOKUP(J23,'Names with Seat Code'!A:E,4,FALSE) | L23: =VLOOKUP(J23,'Names with Seat Code'!A:F,6,FALSE) -> 0
A24: UPPER | B24: O | C24: 112 | D24: LEFT | E24: 1 | F24: 6 | G24: =VLOOKUP(J24,'Names with Seat Code'!A:I,9,FALSE) -> 0 | H24: =VLOOKUP(J24,'Names with Seat Code'!A:E,5,FALSE) -> Anderson | I24: =VLOOKUP(J24,'Names with Seat Code'!A:E,3,FALSE) -> Barrington | J24: 11 | K24: =VLOOKUP(J24,'Names with Seat Code'!A:E,4,FALSE) | L24: =VLOOKUP(J24,'Names with Seat Code'!A:F,6,FALSE) -> 0
A25: UPPER | B25: O | C25: 110 | D25: LEFT | E25: 1 | F25: 7 | G25: =VLOOKUP(J25,'Names with Seat Code'!A:I,9,FALSE) -> 0 | H25: =VLOOKUP(J25,'Names with Seat Code'!A:E,5,FALSE) -> Aquino | I25: =VLOOKUP(J25,'Names with Seat Code'!A:E,3,FALSE) -> Isabella | J25: 12 | K25: =VLOOKUP(J25,'Names with Seat Code'!A:E,4,FALSE) | L25: =VLOOKUP(J25,'Names with Seat Code'!A:F,6,FALSE) -> Isabell-uh Ah-kee-no
A26: UPPER | B26: O | C26: 108 | D26: LEFT | E26: 1 | F26: 8 | G26: =VLOOKUP(J26,'Names with Seat Code'!A:I,9,FALSE) -> 0 | H26: =VLOOKUP(J26,'Names with Seat Code'!A:E,5,FALSE) -> Aquino | I26: =VLOOKUP(J26,'Names with Seat Code'!A:E,3,FALSE) -> Lucas | J26: 13 | K26: =VLOOKUP(J26,'Names with Seat Code'!A:E,4,FALSE) | L26: =VLOOKUP(J26,'Names with Seat Code'!A:F,6,FALSE) -> 0
A27: UPPER | B27: O | C27: 106 | D27: LEFT | E27: 1 | F27: 9 | G27: =VLOOKUP(J27,'Names with Seat Code'!A:I,9,FALSE) -> 0 | H27: =VLOOKUP(J27,'Names with Seat Code'!A:E,5,FALSE) -> Araujo | I27: =VLOOKUP(J27,'Names with Seat Code'!A:E,3,FALSE) -> Tiago | J27: 14 | K27: =VLOOKUP(J27,'Names with Seat Code'!A:E,4,FALSE) | L27: =VLOOKUP(J27,'Names with Seat Code'!A:F,6,FALSE) -> TEE-ah-go AH-ra-joe
A28: UPPER | B28: O | C28: 104 | D28: LEFT | E28: 1 | F28: 10 | G28: =VLOOKUP(J28,'Names with Seat Code'!A:I,9,FALSE) -> 0 | H28: =VLOOKUP(J28,'Names with Seat Code'!A:E,5,FALSE) -> Aretusi | I28: =VLOOKUP(J28,'Names with Seat Code'!A:E,3,FALSE) -> Chloe | J28: 15 | K28: =VLOOKUP(J28,'Names with Seat Code'!A:E,4,FALSE) | L28: =VLOOKUP(J28,'Names with Seat Code'!A:F,6,FALSE) -> ah-reh-toozy
A29: UPPER | B29: O | C29: 102 | D29: LEFT | E29: 1 | F29: 11 | G29: =VLOOKUP(J29,'Names with Seat Code'!A:I,9,FALSE) -> 0 | H29: =VLOOKUP(J29,'Names with Seat Code'!A:E,5,FALSE) -> Audley | I29: =VLOOKUP(J29,'Names with Seat Code'!A:E,3,FALSE) -> Evan | J29: 16 | K29: =VLOOKUP(J29,'Names with Seat Code'!A:E,4,FALSE) | L29: =VLOOKUP(J29,'Names with Seat Code'!A:F,6,FALSE) -> 0
... A102: UPPER | B102: P | C102: 3 | D102: LEFT | E102: 4 | F102: 12 | G102: =VLOOKUP(J102,'Names with Seat Code'!A:I,9,FALSE) -> 0 | H102: =VLOOKUP(J102,'Names with Seat Code'!A:E,5,FALSE) -> Gauvin | I102: =VLOOKUP(J102,'Names with Seat Code'!A:E,3,FALSE) -> Brendan | J102: 89 | K102: =VLOOKUP(J102,'Names with Seat Code'!A:E,4,FALSE) | L102: =VLOOKUP(J102,'Names with Seat Code'!A:F,6,FALSE) -> Gau-vin
A103: LOWER | B103: E | C103: 101 | D103: RIGHT | E103: =E79+1 -> 5 | F103: 1 | G103: =VLOOKUP(J103,'Names with Seat Code'!A:I,9,FALSE) -> 0 | H103: =VLOOKUP(J103,'Names with Seat Code'!A:E,5,FALSE) -> Gebeyaw | I103: =VLOOKUP(J103,'Names with Seat Code'!A:E,3,FALSE) -> Bereket | J103: 90 | K103: =VLOOKUP(J103,'Names with Seat Code'!A:E,4,FALSE) | L103: =VLOOKUP(J103,'Names with Seat Code'!A:F,6,FALSE) -> 0
A104: LOWER | B104: E | C104: 102 | D104: RIGHT | E104: =E80+1 -> 5 | F104: 2 | G104: =VLOOKUP(J104,'Names with Seat Code'!A:I,9,FALSE) -> 0 | H104: =VLOOKUP(J104,'Names with Seat Code'!A:E,5,FALSE) -> Gellot | I104: =VLOOKUP(J104,'Names with Seat Code'!A:E,3,FALSE) -> Alix | J104: 91 | K104: =VLOOKUP(J104,'Names with Seat Code'!A:E,4,FALSE) | L104: =VLOOKUP(J104,'Names with Seat Code'!A:F,6,FALSE) -> 0
A105: LOWER | B105: E | C105: 103 | D105: RIGHT | E105: =E81+1 -> 5 | F105: 3 | G105: =VLOOKUP(J105,'Names with Seat Code'!A:I,9,FALSE) -> 0 | H105: =VLOOKUP(J105,'Names with Seat Code'!A:E,5,FALSE) -> Gigler | I105: =VLOOKUP(J105,'Names with Seat Code'!A:E,3,FALSE) -> Cameron | J105: 92 | K105: =VLOOKUP(J105,'Names with Seat Code'!A:E,4,FALSE) | L105: =VLOOKUP(J105,'Names with Seat Code'!A:F,6,FALSE) -> 0
A106: LOWER | B106: E | C106: 104 | D106: RIGHT | E106: =E82+1 -> 5 | F106: 4 | G106: =VLOOKUP(J106,'Names with Seat Code'!A:I,9,FALSE) -> 0 | H106: =VLOOKUP(J106,'Names with Seat Code'!A:E,5,FALSE) -> Gisetto | I106: =VLOOKUP(J106,'Names with Seat Code'!A:E,3,FALSE) -> Alex | J106: 93 | K106: =VLOOKUP(J106,'Names with Seat Code'!A:E,4,FALSE) | L106: =VLOOKUP(J106,'Names with Seat Code'!A:F,6,FALSE) -> 0
A107: LOWER | B107: E | C107: 105 | D107: RIGHT | E107: =E83+1 -> 5 | F107: 5 | G107: =VLOOKUP(J107,'Names with Seat Code'!A:I,9,FALSE) -> 0 | H107: =VLOOKUP(J107,'Names with Seat Code'!A:E,5,FALSE) -> Goldlust | I107: =VLOOKUP(J107,'Names with Seat Code'!A:E,3,FALSE) -> Benjamin | J107: 94 | K107: =VLOOKUP(J107,'Names with Seat Code'!A:E,4,FALSE) | L107: =VLOOKUP(J107,'Names with Seat Code'!A:F,6,FALSE) -> 0
A108: LOWER | B108: E | C108: 106 | D108: RIGHT | E108: =E84+1 -> 5 | F108: 6 | G108: =VLOOKUP(J108,'Names with Seat Code'!A:I,9,FALSE) -> 0 | H108: =VLOOKUP(J108,'Names with Seat Code'!A:E,5,FALSE) -> Goodfellow | I108: =VLOOKUP(J108,'Names with Seat Code'!A:E,3,FALSE) -> Jack | J108: 95 | K108: =VLOOKUP(J108,'Names with Seat Code'!A:E,4,FALSE) | L108: =VLOOKUP(J108,'Names with Seat Code'!A:F,6,FALSE) -> 0
A109: LOWER | B109: E | C109: 107 | D109: RIGHT | E109: =E85+1 -> 5 | F109: 7 | G109: =VLOOKUP(J109,'Names with Seat Code'!A:I,9,FALSE) -> 0 | H109: =VLOOKUP(J109,'Names with Seat Code'!A:E,5,FALSE) -> Gorski | I109: =VLOOKUP(J109,'Names with Seat Code'!A:E,3,FALSE) -> Drew | J109: 96 | K109: =VLOOKUP(J109,'Names with Seat Code'!A:E,4,FALSE) | L109: =VLOOKUP(J109,'Names with Seat Code'!A:F,6,FALSE) -> Drew
A110: LOWER | B110: E | C110: 108 | D110: RIGHT | E110: =E86+1 -> 5 | F110: 8 | G110: =VLOOKUP(J110,'Names with Seat Code'!A:I,9,FALSE) -> 0 | H110: =VLOOKUP(J110,'Names with Seat Code'!A:E,5,FALSE) -> Gosdanian | I110: =VLOOKUP(J110,'Names with Seat Code'!A:E,3,FALSE) -> Lila | J110: 97 | K110: =VLOOKUP(J110,'Names with Seat Code'!A:E,4,FALSE) | L110: =VLOOKUP(J110,'Names with Seat Code'!A:F,6,FALSE) -> Lylah Gosdainian
A111: LOWER | B111: E | C111: 109 | D111: RIGHT | E111: =E87+1 -> 5 | F111: 9 | G111: =VLOOKUP(J111,'Names with Seat Code'!A:I,9,FALSE) -> 0 | H111: =VLOOKUP(J111,'Names with Seat Code'!A:E,5,FALSE) -> Grant | I111: =VLOOKUP(J111,'Names with Seat Code'!A:E,3,FALSE) -> Cole | J111: 98 | K111: =VLOOKUP(J111,'Names with Seat Code'!A:E,4,FALSE) -> Sebastian | L111: =VLOOKUP(J111,'Names with Seat Code'!A:F,6,FALSE) -> 0
A112: LOWER | B112: E | C112: 110 | D112: RIGHT | E112: =E88+1 -> 5 | F112: 10 | G112: =VLOOKUP(J112,'Names with Seat Code'!A:I,9,FALSE) -> 0 | H112: =VLOOKUP(J112,'Names with Seat Code'!A:E,5,FALSE) -> Graves | I112: =VLOOKUP(J112,'Names with Seat Code'!A:E,3,FALSE) -> Kendall | J112: 99 | K112: =VLOOKUP(J112,'Names with Seat Code'!A:E,4,FALSE) | L112: =VLOOKUP(J112,'Names with Seat Code'!A:F,6,FALSE) -> 0
...

Sheet Grad Breaks for Print
A1: SECTION | B1: ROW | C1: SEAT NUMBER | D1: LINE NUMBER | E1: SIDE | F1: ROW | G1: SEAT NUMBER | H1: First Name | I1: Last Name
A2: STAGE | C2: 1a | D2: Leader | E2: STAGE | G2: 1a | H2: ='Grad Raw Data'!I2 -> Amelia | I2: ='Grad Raw Data'!H2 -> Borawski | J2: ='Grad Raw Data'!G2 -> 0
A3: STAGE | C3: 1b | D3: Leader | E3: STAGE | G3: 1b | H3: ='Grad Raw Data'!I3 -> - | I3: ='Grad Raw Data'!H3 -> - | J3: ='Grad Raw Data'!G3 -> 0
A4: STAGE | C4: 2 | D4: Leader | E4: STAGE | G4: 2 | H4: ='Grad Raw Data'!H4 -> Boyko | I4: ='Grad Raw Data'!I4 -> Indigo | J4: ='Grad Raw Data'!G4 -> 0
A5: STAGE | C5: 3 | D5: Leader | E5: STAGE | G5: 3 | H5: ='Grad Raw Data'!I5 -> Jason | I5: ='Grad Raw Data'!I5 -> Jason | J5: ='Grad Raw Data'!G5 -> 0
A6: STAGE | C6: 4 | D6: Leader | E6: STAGE | G6: 4 | H6: ='Grad Raw Data'!I6 -> Jessica | I6: ='Grad Raw Data'!H6 -> Wong
A7: LOWER | B7: A | C7: 101 | D7: =(F7-1)*12+G7 -> 1 | E7: RIGHT | F7: 1 | G7: 1 | H7: ='Grad Raw Data'!I7 -> Clara | I7: ='Grad Raw Data'!H7 -> Healy | J7: ='Grad Raw Data'!G7 -> 0
A8: LOWER | B8: A | C8: 102 | D8: =(F8-1)*12+G8 -> 2 | E8: RIGHT | F8: 1 | G8: 2 | H8: ='Grad Raw Data'!I8 -> Samuel | I8: ='Grad Raw Data'!H8 -> Hillery | J8: ='Grad Raw Data'!G8 -> 0
A9: LOWER | B9: A | C9: 103 | D9: =(F9-1)*12+G9 -> 3 | E9: RIGHT | F9: 1 | G9: 3 | H9: ='Grad Raw Data'!I9 -> Piper | I9: ='Grad Raw Data'!H9 -> Martin | J9: ='Grad Raw Data'!G9 -> 0
A10: LOWER | B10: A | C10: 104 | D10: =(F10-1)*12+G10 -> 4 | E10: RIGHT | F10: 1 | G10: 4 | H10: ='Grad Raw Data'!I10 -> Aidan | I10: ='Grad Raw Data'!H10 -> Mullin | J10: ='Grad Raw Data'!G10 -> 0
A11: LOWER | B11: A | C11: 105 | D11: =(F11-1)*12+G11 -> 5 | E11: RIGHT | F11: 1 | G11: 5 | H11: ='Grad Raw Data'!I11 -> Emma | I11: ='Grad Raw Data'!H11 -> Nelson | J11: ='Grad Raw Data'!G11 -> 0
A12: LOWER | B12: A | C12: 106 | D12: =(F12-1)*12+G12 -> 6 | E12: RIGHT | F12: 1 | G12: 6 | H12: ='Grad Raw Data'!I12 -> Thomas | I12: ='Grad Raw Data'!H12 -> Stathoulopoulos | J12: ='Grad Raw Data'!G12 -> 0
A13: LOWER | B13: A | C13: 107 | D13: =(F13-1)*12+G13 -> 7 | E13: RIGHT | F13: 1 | G13: 7 | H13: ='Grad Raw Data'!I13 -> Cara | I13: ='Grad Raw Data'!H13 -> Vitarisi | J13: ='Grad Raw Data'!G13 -> 0
A14: LOWER | B14: A | C14: 108 | D14: =(F14-1)*12+G14 -> 8 | E14: RIGHT | F14: 1 | G14: 8 | H14: ='Grad Raw Data'!I14 -> Jillian | I14: ='Grad Raw Data'!H14 -> Abate | J14: ='Grad Raw Data'!G14 -> 0
A15: LOWER | B15: A | C15: 109 | D15: =(F15-1)*12+G15 -> 9 | E15: RIGHT | F15: 1 | G15: 9 | H15: ='Grad Raw Data'!I15 -> Logan | I15: ='Grad Raw Data'!H15 -> Abrams | J15: ='Grad Raw Data'!G15 -> 0
A16: LOWER | B16: A | C16: 110 | D16: =(F16-1)*12+G16 -> 10 | E16: RIGHT | F16: 1 | G16: 10 | H16: ='Grad Raw Data'!I16 -> Raniya | I16: ='Grad Raw Data'!H16 -> Abubakar | J16: ='Grad Raw Data'!G16 -> 0
A17: LOWER | B17: A | C17: 111 | D17: =(F17-1)*12+G17 -> 11 | E17: RIGHT | F17: 1 | G17: 11 | H17: ='Grad Raw Data'!I17 -> Luis | I17: ='Grad Raw Data'!H17 -> Aburto Campos | J17: ='Grad Raw Data'!G17 -> 0
A18: LOWER | B18: A | C18: 112 | D18: =(F18-1)*12+G18 -> 12 | E18: RIGHT | F18: 1 | G18: 12 | H18: ='Grad Raw Data'!I18 -> Devyn | I18: ='Grad Raw Data'!H18 -> Ahlert | J18: ='Grad Raw Data'!G18 -> 0
... A102: UPPER | B102: P | C102: 3 | D102: =(F102-1)*12+G102 -> 48 | E102: LEFT | F102: 4 | G102: 12 | H102: ='Grad Raw Data'!I102 -> Brendan | I102: ='Grad Raw Data'!H102 -> Gauvin | J102: ='Grad Raw Data'!G102 -> 0
A103: LOWER | B103: E | C103: 101 | D103: =(F103-1)*12+G103 -> 49 | E103: RIGHT | F103: =F79+1 -> 5 | G103: 1 | H103: ='Grad Raw Data'!I103 -> Bereket | I103: ='Grad Raw Data'!H103 -> Gebeyaw | J103: ='Grad Raw Data'!G103 -> 0
A104: LOWER | B104: E | C104: 102 | D104: =(F104-1)*12+G104 -> 50 | E104: RIGHT | F104: =F80+1 -> 5 | G104: 2 | H104: ='Grad Raw Data'!I104 -> Alix | I104: ='Grad Raw Data'!H104 -> Gellot | J104: ='Grad Raw Data'!G104 -> 0
A105: LOWER | B105: E | C105: 103 | D105: =(F105-1)*12+G105 -> 51 | E105: RIGHT | F105: =F81+1 -> 5 | G105: 3 | H105: ='Grad Raw Data'!I105 -> Cameron | I105: ='Grad Raw Data'!H105 -> Gigler | J105: ='Grad Raw Data'!G105 -> 0
A106: LOWER | B106: E | C106: 104 | D106: =(F106-1)*12+G106 -> 52 | E106: RIGHT | F106: =F82+1 -> 5 | G106: 4 | H106: ='Grad Raw Data'!I106 -> Alex | I106: ='Grad Raw Data'!H106 -> Gisetto | J106: ='Grad Raw Data'!G106 -> 0
A107: LOWER | B107: E | C107: 105 | D107: =(F107-1)*12+G107 -> 53 | E107: RIGHT | F107: =F83+1 -> 5 | G107: 5 | H107: ='Grad Raw Data'!I107 -> Benjamin | I107: ='Grad Raw Data'!H107 -> Goldlust | J107: ='Grad Raw Data'!G107 -> 0
A108: LOWER | B108: E | C108: 106 | D108: =(F108-1)*12+G108 -> 54 | E108: RIGHT | F108: =F84+1 -> 5 | G108: 6 | H108: ='Grad Raw Data'!I108 -> Jack | I108: ='Grad Raw Data'!H108 -> Goodfellow | J108: ='Grad Raw Data'!G108 -> 0
A109: LOWER | B109: E | C109: 107 | D109: =(F109-1)*12+G109 -> 55 | E109: RIGHT | F109: =F85+1 -> 5 | G109: 7 | H109: ='Grad Raw Data'!I109 -> Drew | I109: ='Grad Raw Data'!H109 -> Gorski | J109: ='Grad Raw Data'!G109 -> 0
A110: LOWER | B110: E | C110: 108 | D110: =(F110-1)*12+G110 -> 56 | E110: RIGHT | F110: =F86+1 -> 5 | G110: 8 | H110: ='Grad Raw Data'!I110 -> Lila | I110: ='Grad Raw Data'!H110 -> Gosdanian | J110: ='Grad Raw Data'!G110 -> 0
A111: LOWER | B111: E | C111: 109 | D111: =(F111-1)*12+G111 -> 57 | E111: RIGHT | F111: =F87+1 -> 5 | G111: 9 | H111: ='Grad Raw Data'!I111 -> Cole | I111: ='Grad Raw Data'!H111 -> Grant | J111: ='Grad Raw Data'!G111 -> 0
A112: LOWER | B112: E | C112: 110 | D112: =(F112-1)*12+G112 -> 58 | E112: RIGHT | F112: =F88+1 -> 5 | G112: 10 | H112: ='Grad Raw Data'!I112 -> Kendall | I112: ='Grad Raw Data'!H112 -> Graves | J112: ='Grad Raw Data'!G112 -> 0
A113: LOWER | B113: E | C113: 111 | D113: =(F113-1)*12+G113 -> 59 | E113: RIGHT | F113: =F89+1 -> 5 | G113: 11 | H113: ='Grad Raw Data'!I113 -> Griffin | I113: ='Grad Raw Data'!H113 -> Haggerty | J113: ='Grad Raw Data'!G113 -> 0
A114: LOWER | B114: E | C114: 112 | D114: =(F114-1)*12+G114 -> 60 | E114: RIGHT | F114: =F90+1 -> 5 | G114: 12 | H114: ='Grad Raw Data'!I114 -> Andrea | I114: ='Grad Raw Data'!H114 -> Hall | J114: ='Grad Raw Data'!G114 -> 0
... A258: LOWER | B258: L | C258: 112 | D258: =(F258-1)*12+G258 -> 132 | E258: RIGHT | F258: =F234+1 -> 11 | G258: 12 | H258: ='Grad Raw Data'!I258 -> #N/A | I258: ='Grad Raw Data'!H258 -> #N/A | J258: ='Grad Raw Data'!G258 -> #N/A
A259: UPPER | B259: T | C259: 126 | D259: 121 | E259: LEFT | F259: 11 | G259: 1 | H259: ='Grad Raw Data'!I259 -> Aidan | I259: ='Grad Raw Data'!H259 -> Williams | J259: ='Grad Raw Data'!G259 -> 0
A260: UPPER | B260: T | C260: 124 | D260: 122 | E260: LEFT | F260: 11 | G260: 2 | H260: ='Grad Raw Data'!I260 -> Jamari | I260: ='Grad Raw Data'!H260 -> Wright | J260: ='Grad Raw Data'!G260 -> 0
A261: UPPER | B261: T | C261: 122 | D261: 123 | E261: LEFT | F261: 11 | G261: 3 | H261: ='Grad Raw Data'!I261 -> Jared | I261: ='Grad Raw Data'!H261 -> Wright | J261: ='Grad Raw Data'!G261 -> 0
A262: UPPER | B262: T | C262: 120 | D262: 124 | E262: LEFT | F262: 11 | G262: 4 | H262: ='Grad Raw Data'!I262 -> Quinn | I262: ='Grad Raw Data'!H262 -> Yandle | J262: ='Grad Raw Data'!G262 -> 0
A263: UPPER | B263: T | C263: 118 | D263: 125 | E263: LEFT | F263: 11 | G263: 5 | H263: ='Grad Raw Data'!I263 -> John | I263: ='Grad Raw Data'!H263 -> Zani | J263: ='Grad Raw Data'!G263 -> 0
A264: UPPER | B264: T | C264: 116 | D264: 126 | E264: LEFT | F264: 11 | G264: 6 | H264: ='Grad Raw Data'!I264 -> Jiayu | I264: ='Grad Raw Data'!H264 -> Zheng | J264: ='Grad Raw Data'!G264 -> 0
A265: UPPER | B265: T | C265: 114 | D265: 127 | E265: LEFT | F265: 11 | G265: 7 | H265: ='Grad Raw Data'!I265 -> #N/A | I265: ='Grad Raw Data'!H265 -> #N/A | J265: ='Grad Raw Data'!G265 -> #N/A
A266: UPPER | B266: T | C266: 112 | D266: 128 | E266: LEFT | F266: 11 | G266: 8 | H266: ='Grad Raw Data'!I266 -> #N/A | I266: ='Grad Raw Data'!H266 -> #N/A | J266: ='Grad Raw Data'!G266 -> #N/A
...

Sheet Grad Pages for Podium with pron
A1: First | B1: Middle | C1: Last | D1: Side | E1: Row
A2: ='Grad Raw Data'!I2 -> Amelia | B2: ='Grad Raw Data'!K2 -> Jane | C2: ='Grad Raw Data'!H2 -> Borawski | D2: ='Grad Raw Data'!D2 -> STAGE | E2: ='Grad Raw Data'!E2 -> STAGE | G2: 2 | H2: =IF(MOD((G2+2)/1,2)=0,(G2/2+1),"") -> 2
G3: 3 | H3: =IF(MOD((G3+2)/1,2)=0,(G3/2+1),"")
A4: ='Grad Raw Data'!I3 -> - | B4: ='Grad Raw Data'!K4 | C4: ='Grad Raw Data'!H3 -> - | D4: ='Grad Raw Data'!D4 -> STAGE | E4: ='Grad Raw Data'!E4 -> STAGE | G4: 4 | H4: =IF(MOD((G4+2)/1,2)=0,(G4/2+1),"") -> 3
G5: 5 | H5: =IF(MOD((G5+2)/1,2)=0,(G5/2+1),"")
A6: ='Grad Raw Data'!I4 -> Indigo | B6: ='Grad Raw Data'!K4 | C6: ='Grad Raw Data'!H4 -> Boyko | D6: ='Grad Raw Data'!D4 -> STAGE | E6: ='Grad Raw Data'!E4 -> STAGE | G6: 6 | H6: =IF(MOD((G6+2)/1,2)=0,(G6/2+1),"") -> 4
G7: 7 | H7: =IF(MOD((G7+2)/1,2)=0,(G7/2+1),"")
A8: ='Grad Raw Data'!I5 -> Jason | B8: ='Grad Raw Data'!K5 | C8: ='Grad Raw Data'!H5 -> Walsh | D8: ='Grad Raw Data'!D5 -> STAGE | E8: ='Grad Raw Data'!E5 -> STAGE | G8: 8 | H8: =IF(MOD((G8+2)/1,2)=0,(G8/2+1),"") -> 5
G9: 9 | H9: =IF(MOD((G9+2)/1,2)=0,(G9/2+1),"")
